Workbook

Sheet 使用说明
B2: 亚马逊 FBA · 9810 出口海外仓 核销台账
B3: 用一个「核销编号」（报关单号-项号）把一批货从报关出口、亚马逊入仓、销售、回款收汇，一直到退税核算串起来，逐项销账。每批货走到哪一步、还剩多少没卖、钱回没回、退税要不要核算，都在「核销总表」一眼看清。
B5: 一、整体流程
B6: ① 报关出口 9810报关单 | C6: ② 亚马逊入仓 FBA签收 | D6: ③ 销售核销 按月分配到报关单 | E6: ④ 回款收汇 结算→境内入账 | F6: ⑤ 退税与核算 预退税到期核算
B7: 填在「①出口报关」 | C7: 填在「①出口报关」 | D7: 填在「②销售核销」 异常记「⑤库存异常」 | E7: 填在「③回款收汇」 | F7: 填在「④退税核算」 单证记「⑥单证留存」
B9: 二、各表怎么用
B10: 表名 | C10: 记什么 | D10: 一行代表 | E10: 多久更新 | F10: 数据从哪来
B11: 核销总表 | C11: 每批货走到哪一步、有没有风险 | D11: 一个核销编号 | E11: 自动，无需填写 | F11: 汇总下面各表
B12: ①出口报关 | C12: 报关单、FBA货件、进项发票、亚马逊签收 | D12: 报关单的一个项号 | E12: 每票报关后 | F12: 报关单、亚马逊货件页面、进项发票
B13: ②销售核销 | C13: 每月卖了多少、退回多少、属于哪票报关单 | D13: 一个月×一个SKU×一个核销编号 | E13: 每月结算报告出来后 | F13: 结算报告、库存分类账
B14: ③回款收汇 | C14: 每份结算报告的扣费、净额、到账、结汇 | D14: 一份结算报告 | E14: 每次回款/提现 | F14: 结算报告、收款平台提现记录、银行水单
B15: ④退税核算 | C15: 退税申报、预退税核算期限与结果 | D15: 一次退税申报 | E15: 每次申报/核算 | F15: 电子税务局或国际贸易单一窗口
B16: ⑤库存异常 | C16: 弃置、丢失赔偿、移除、退运回国 | D16: 一次异常 | E16: 发生时 | F16: 库存分类账、赔偿报告、移除订单
B17: ⑥单证留存 | C17: 备案单证是否收齐、放在哪 | D17: 一张报关单 | E17: 退税申报后15日内 | F17: 公司文件夹
B18: 参数表 | C18: 企业类型、SKU档案、下拉选项 | D18: 一个SKU | E18: 新品上架时 | F18: 内部资料
B20: 三、关键期限（截至2026年10月的现行规定）
B21: 事项 | D21: 期限 | F21: 依据
B22: 报关时向海关传输订仓单电子数据；海外仓不用再向海关备案 | D22: 每次报关 | F22: 海关总署公告2024年第167号（2024年12月15日起）
B23: 未卖出的货可先申报「预退税」，申报表业务类型填 HWC-YT；已卖出的按现行规定申报 | D23: 报关离境后即可申报 | F23: 税务总局公告2025年第3号
B24: 退税申报后留存备案单证（合同或订仓单、运输单据、委托报关单据等），按申报时间编目录 | D24: 申报后15日内留存；保存10年 | F24: 税务总局公告2026年第5号 第45条
B25: 预退税的货卖出后，留存销售佐证（结算报告、销售明细账、记账凭证等） | D25: 实现销售后15日内 | F25: 税务总局公告2025年第3号
B26: 预退税核算 | D26: 税务办结次月1日至次年4月30日；生产企业最迟在次年4月增值税申报期截止日前 | F26: 税务总局公告2025年第3号
B27: 核算时还没卖出 | D27: 全额缴回预退税；卖出后再按现行规定重新申报 | F27: 税务总局公告2025年第3号
B28: 到期没核算 | D28: 税务机关追回已退的预退税 | F28: 税务总局公告2025年第3号
B29: 收汇 | D29: 报关出口之日的次年4月30日前（符合视同收汇情形的留存举证材料） | F29: 税务总局公告2026年第5号 第48条
B30: 已退税的货发生退回、不再适用退税等 | D30: 发生当月或次月用负数冲减原申报 | F30: 税务总局公告2026年第5号 第29条
B32: 四、回款要注意
B33: 1. 亚马逊打款是扣完佣金、配送费、仓储费、广告费后的净额。「③回款收汇」把毛额、各项扣费、净额分开记，需要时可以还原成毛额。
B34: 2. 过去明确允许跨境电商把境外仓储、物流、税费与货款轧差结算、海外仓按实际销售收汇的文件（汇发〔2020〕11号），已在2025年10月被汇发〔2025〕47号废止。新文件明确写到的轧差路径是外贸综合服务企业代办、试点地区优质企业等情形。按净额办理收汇前，先和收款银行确认口径。
B35: 3. 银行办理跨境电商收汇时，涉外收支申报附言应注明「跨境电商」（汇发〔2025〕47号第五条）。
B36: 4. 退税申报时一般不用报送收汇材料，但要留存备查；在报关出口次年4月30日之后才申报、或企业为四类管理的，需要报送（税务总局公告2026年第5号第49条）。
B38: 五、填写规则
B39: 1. 先到「参数表」选企业类型，并建好SKU档案。外贸企业的预计退税额按进项发票不含税金额计算，生产企业按FOB人民币金额估算（免抵退的实际金额以申报系统为准）。
B40: 2. 白底格子手填；浅蓝色格子是公式，不要改动。表头带「（自动）」的列都是公式。
B41: 3. 同一SKU有多票报关单时，销量按出口日期「先进先出」：先分配给最早那票，卖完再分下一票。「核销总表」的在仓未售数可以帮你判断还剩哪票。
B42: 4. 一份结算报告的净额要全部分配到报关单，「③回款收汇」的分摊差异为 0 才算分完。
B43: 5. 买家退货回到可售库存，记在「②销售核销」的退货数量；不可售弃置、丢失赔偿、移除、退运回国等，记在「⑤库存异常」。
B44: 6. 各表中备注为「示例」的行用于演示公式效果，正式使用前请删除这些行的手填内容（浅蓝色公式格保留）。
... B47: 六、颜色说明
B48: 表头 | C48: 手填列的表头
...

Sheet 核销总表
A1: 核销总表
A2: 每个核销编号（报关单号-项号）一行，全部自动计算，无需手填。先看最右列「需要关注」，红色优先处理。
A3: 报关项数 | C3: 报关总数量 | E3: 累计净售出 | G3: 在仓未售 | I3: 已申报退税额（元） | K3: 其中预退税额（元） | M3: 预退税待核算（项） | O3: 已逾期/超期（项） | Q3: 单证不齐（项）
A4: =COUNTIF($A$7:$A$306,"?*") -> 2 | C4: =SUM($E$7:$E$306) -> 1500 | E4: =SUM($H$7:$H$306) -> 885 | G4: =SUM($J$7:$J$306) -> 608 | I4: =SUM($P$7:$P$306) -> 7540 | K4: =SUM($Q$7:$Q$306) -> 7540 | M4: =COUNTIF($S$7:$S$306,"待核算")+COUNTIF($S$7:$S$306,"临近截止") -> 2 | O4: =COUNTIF($S$7:$S$306,"已逾期")+COUNTIF($O$7:$O$306,"超期未收汇")+COUNTIF($O$7:$O$306,"超过收汇期限仍未销售") -> 0 | Q4: =COUNTIF($T$7:$T$306,"缺*")+COUNTIF($T$7:$T$306,"未登记") -> 0
A6: 核销编号 | B6: SKU | C6: 品名 | D6: 出口日期 | E6: 报关数量 | F6: 签收数量 | G6: 入仓差异 | H6: 累计净售出 | I6: 异常减少 | J6: 在仓未售 | K6: 销售进度 | L6: 累计净回款（原币） | M6: 其中已收汇（原币） | N6: 收汇截止日 | O6: 收汇状态 | P6: 已申报退税额（元） | Q6: 其中预退税额（元） | R6: 核算期末 | S6: 核算状态 | T6: 单证情况 | U6: 需要关注
A7: =IF(①出口报关!A4="","",①出口报关!A4) -> 530120260000000001-1 | B7: =IF($A7="","",①出口报关!I4) -> DEMO-A01 | C7: =IF($A7="","",①出口报关!J4) -> 示例商品A | D7: =IF($A7="","",IF(①出口报关!D4="","",①出口报关!D4)) -> 46091 | E7: =IF($A7="","",N(①出口报关!L4)) -> 1000 | F7: =IF($A7="","",IF(①出口报关!Y4="","未签收",①出口报关!Y4)) -> 996 | G7: =IF(OR($A7="",NOT(ISNUMBER(F7))),"",F7-E7) -> -4 | H7: =IF($A7="","",SUMIFS(②销售核销!$I$4:$I$603,②销售核销!$E$4:$E$603,$A7)) -> 685 | I7: =IF($A7="","",SUMIFS(⑤库存异常!$E$4:$E$203,⑤库存异常!$B$4:$B$203,$A7)) -> 3 | J7: =IF($A7="","",IF(ISNUMBER(F7),F7,E7)-H7-I7) -> 308 | K7: =IF(OR($A7="",N(E7)=0),"",H7/E7) -> 0.685 | L7: =IF($A7="","",SUMIFS(②销售核销!$L$4:$L$603,②销售核销!$E$4:$E$603,$A7)) -> 12593 | M7: =IF($A7="","",SUMIFS(②销售核销!$L$4:$L$603,②销售核销!$E$4:$E$603,$A7,②销售核销!$M$4:$M$603,"已收汇")) -> 5397 | N7: =IF(ISNUMBER(D7),DATE(YEAR(D7)+1,4,30),"") -> 46507 | O7: =IF($A7="","",IF(N(H7)=0,IF(AND(ISNUMBER(N7),TODAY()>N7),"超过收汇期限仍未销售","尚未销售"),IF(ROUND(M7,2)>=ROUND(L7,2),"已售部分已收汇",IF(AND(ISNUMBER(N7),TODAY()>N7),"超期未收汇","有回款待收汇")))) -> 有回款待收汇 | P7: =IF($A7="","",SUMIFS(④退税核算!$H$4:$H$303,④退税核算!$A$4:$A$303,$A7)) -> 4680 | Q7: =IF($A7="","",SUMIFS(④退税核算!$H$4:$H$303,④退税核算!$A$4:$A$303,$A7,④退税核算!$D$4:$D$303,"未售-海外仓预退（HWC-YT）")) -> 4680 | R7: =IF($A7="","",IF(COUNTIFS(④退税核算!$A$4:$A$303,$A7,④退税核算!$D$4:$D$303,"未售-海外仓预退（HWC-YT）",④退税核算!$I$4:$I$303,">0")=0,"",_xlfn.MINIFS(④退税核算!$J$4:$J$303,④退税核算!$A$4:$A$303,$A7,④退税核算!$D$4:$D$303,"未售-海外仓预退（HWC-YT）"))) -> 46507 | S7: =IF($A7="","",IF(COUNTIFS(④退税核算!$A$4:$A$303,$A7,④退税核算!$D$4:$D$303,"未售-海外仓预退（HWC-YT）")=0,"不涉及",IF(COUNTIFS(④退税核算!$A$4:$A$303,$A7,④退税核算!$S$4:$S$303,"已逾期*")>0,"已逾期",IF(COUNTIFS(④退税核算!$A$4:$A$303,$A7,④退税核算!$S$4:$S$303,"临近*")>0,"临近截止",IF(COUNTIFS(④退税核算!$A$4:$A$303,$A7,④退税核算!$S$4:$S$303,"待*")>0,"待核算","已核算"))))) -> 待核算 | T7: =IF($A7="","",IFERROR(INDEX(⑥单证留存!$P$4:$P$203,MATCH(①出口报关!B4,⑥单证留存!$A$4:$A$203,0)),"未登记")) -> 齐全 | U7: =IF($A7="","",IF(IF(OR(O7="超期未收汇",O7="超过收汇期限仍未销售")," 收汇超期","")&IF(S7="已逾期"," 核算逾期","")&IF(S7="临近截止"," 核算临近截止","")&IF(LEFT(T7,1)="缺"," 单证"&T7,"")&IF(T7="未登记"," 单证未登记","")&IF(AND(ISNUMBER(G7),N(G7)<>0)," 入仓差异"&G7,"")="","正常",SUBSTITUTE(TRIM(IF(OR(O7="超期未收汇",O7="超过收汇期限仍未销售")," 收汇超期","")&IF(S7="已逾期"," 核算逾期","")&IF(S7="临近截止"," 核算临近截止","")&IF(LEFT(T7,1)="缺"," 单证"&T7,"")&IF(T7="未登记"," 单证未登记","")&IF(AND(ISNUMBER(G7),N(G7)<>0)," 入仓差异"&G7,""))," ","、"))) -> 入仓差异-4
A8: =IF(①出口报关!A5="","",①出口报关!A5) -> 530120260000000001-2 | B8: =IF($A8="","",①出口报关!I5) -> DEMO-B02 | C8: =IF($A8="","",①出口报关!J5) -> 示例商品B | D8: =IF($A8="","",IF(①出口报关!D5="","",①出口报关!D5)) -> 46091 | E8: =IF($A8="","",N(①出口报关!L5)) -> 500 | F8: =IF($A8="","",IF(①出口报关!Y5="","未签收",①出口报关!Y5)) -> 500 | G8: =IF(OR($A8="",NOT(ISNUMBER(F8))),"",F8-E8) -> 0 | H8: =IF($A8="","",SUMIFS(②销售核销!$I$4:$I$603,②销售核销!$E$4:$E$603,$A8)) -> 200 | I8: =IF($A8="","",SUMIFS(⑤库存异常!$E$4:$E$203,⑤库存异常!$B$4:$B$203,$A8)) -> 0 | J8: =IF($A8="","",IF(ISNUMBER(F8),F8,E8)-H8-I8) -> 300 | K8: =IF(OR($A8="",N(E8)=0),"",H8/E8) -> 0.4 | L8: =IF($A8="","",SUMIFS(②销售核销!$L$4:$L$603,②销售核销!$E$4:$E$603,$A8)) -> 4798 | M8: =IF($A8="","",SUMIFS(②销售核销!$L$4:$L$603,②销售核销!$E$4:$E$603,$A8,②销售核销!$M$4:$M$603,"已收汇")) -> 4798 | N8: =IF(ISNUMBER(D8),DATE(YEAR(D8)+1,4,30),"") -> 46507 | O8: =IF($A8="","",IF(N(H8)=0,IF(AND(ISNUMBER(N8),TODAY()>N8),"超过收汇期限仍未销售","尚未销售"),IF(ROUND(M8,2)>=ROUND(L8,2),"已售部分已收汇",IF(AND(ISNUMBER(N8),TODAY()>N8),"超期未收汇","有回款待收汇")))) -> 已售部分已收汇 | P8: =IF($A8="","",SUMIFS(④退税核算!$H$4:$H$303,④退税核算!$A$4:$A$303,$A8)) -> 2860 | Q8: =IF($A8="","",SUMIFS(④退税核算!$H$4:$H$303,④退税核算!$A$4:$A$303,$A8,④退税核算!$D$4:$D$303,"未售-海外仓预退（HWC-YT）")) -> 2860 | R8: =IF($A8="","",IF(COUNTIFS(④退税核算!$A$4:$A$303,$A8,④退税核算!$D$4:$D$303,"未售-海外仓预退（HWC-YT）",④退税核算!$I$4:$I$303,">0")=0,"",_xlfn.MINIFS(④退税核算!$J$4:$J$303,④退税核算!$A$4:$A$303,$A8,④退税核算!$D$4:$D$303,"未售-海外仓预退（HWC-YT）"))) -> 46507 | S8: =IF($A8="","",IF(COUNTIFS(④退税核算!$A$4:$A$303,$A8,④退税核算!$D$4:$D$303,"未售-海外仓预退（HWC-YT）")=0,"不涉及",IF(COUNTIFS(④退税核算!$A$4:$A$303,$A8,④退税核算!$S$4:$S$303,"已逾期*")>0,"已逾期",IF(COUNTIFS(④退税核算!$A$4:$A$303,$A8,④退税核算!$S$4:$S$303,"临近*")>0,"临近截止",IF(COUNTIFS(④退税核算!$A$4:$A$303,$A8,④退税核算!$S$4:$S$303,"待*")>0,"待核算","已核算"))))) -> 待核算 | T8: =IF($A8="","",IFERROR(INDEX(⑥单证留存!$P$4:$P$203,MATCH(①出口报关!B5,⑥单证留存!$A$4:$A$203,0)),"未登记")) -> 齐全 | U8: =IF($A8="","",IF(IF(OR(O8="超期未收汇",O8="超过收汇期限仍未销售")," 收汇超期","")&IF(S8="已逾期"," 核算逾期","")&IF(S8="临近截止"," 核算临近截止","")&IF(LEFT(T8,1)="缺"," 单证"&T8,"")&IF(T8="未登记"," 单证未登记","")&IF(AND(ISNUMBER(G8),N(G8)<>0)," 入仓差异"&G8,"")="","正常",SUBSTITUTE(TRIM(IF(OR(O8="超期未收汇",O8="超过收汇期限仍未销售")," 收汇超期","")&IF(S8="已逾期"," 核算逾期","")&IF(S8="临近截止"," 核算临近截止","")&IF(LEFT(T8,1)="缺"," 单证"&T8,"")&IF(T8="未登记"," 单证未登记","")&IF(AND(ISNUMBER(G8),N(G8)<>0)," 入仓差异"&G8,""))," ","、"))) -> 正常
A9: =IF(①出口报关!A6="","",①出口报关!A6) | B9: =IF($A9="","",①出口报关!I6) | C9: =IF($A9="","",①出口报关!J6) | D9: =IF($A9="","",IF(①出口报关!D6="","",①出口报关!D6)) | E9: =IF($A9="","",N(①出口报关!L6)) | F9: =IF($A9="","",IF(①出口报关!Y6="","未签收",①出口报关!Y6)) | G9: =IF(OR($A9="",NOT(ISNUMBER(F9))),"",F9-E9) | H9: =IF($A9="","",SUMIFS(②销售核销!$I$4:$I$603,②销售核销!$E$4:$E$603,$A9)) | I9: =IF($A9="","",SUMIFS(⑤库存异常!$E$4:$E$203,⑤库存异常!$B$4:$B$203,$A9)) | J9: =IF($A9="","",IF(ISNUMBER(F9),F9,E9)-H9-I9) | K9: =IF(OR($A9="",N(E9)=0),"",H9/E9) | L9: =IF($A9="","",SUMIFS(②销售核销!$L$4:$L$603,②销售核销!$E$4:$E$603,$A9)) | M9: =IF($A9="","",SUMIFS(②销售核销!$L$4:$L$603,②销售核销!$E$4:$E$603,$A9,②销售核销!$M$4:$M$603,"已收汇")) | N9: =IF(ISNUMBER(D9),DATE(YEAR(D9)+1,4,30),"") | O9: =IF($A9="","",IF(N(H9)=0,IF(AND(ISNUMBER(N9),TODAY()>N9),"超过收汇期限仍未销售","尚未销售"),IF(ROUND(M9,2)>=ROUND(L9,2),"已售部分已收汇",IF(AND(ISNUMBER(N9),TODAY()>N9),"超期未收汇","有回款待收汇")))) | P9: =IF($A9="","",SUMIFS(④退税核算!$H$4:$H$303,④退税核算!$A$4:$A$303,$A9)) | Q9: =IF($A9="","",SUMIFS(④退税核算!$H$4:$H$303,④退税核算!$A$4:$A$303,$A9,④退税核算!$D$4:$D$303,"未售-海外仓预退（HWC-YT）")) | R9: =IF($A9="","",IF(COUNTIFS(④退税核算!$A$4:$A$303,$A9,④退税核算!$D$4:$D$303,"未售-海外仓预退（HWC-YT）",④退税核算!$I$4:$I$303,">0")=0,"",_xlfn.MINIFS(④退税核算!$J$4:$J$303,④退税核算!$A$4:$A$303,$A9,④退税核算!$D$4:$D$303,"未售-海外仓预退（HWC-YT）"))) | S9: =IF($A9="","",IF(COUNTIFS(④退税核算!$A$4:$A$303,$A9,④退税核算!$D$4:$D$303,"未售-海外仓预退（HWC-YT）")=0,"不涉及",IF(COUNTIFS(④退税核算!$A$4:$A$303,$A9,④退税核算!$S$4:$S$303,"已逾期*")>0,"已逾期",IF(COUNTIFS(④退税核算!$A$4:$A$303,$A9,④退税核算!$S$4:$S$303,"临近*")>0,"临近截止",IF(COUNTIFS(④退税核算!$A$4:$A$303,$A9,④退税核算!$S$4:$S$303,"待*")>0,"待核算","已核算"))))) | T9: =IF($A9="","",IFERROR(INDEX(⑥单证留存!$P$4:$P$203,MATCH(①出口报关!B6,⑥单证留存!$A$4:$A$203,0)),"未登记")) | U9: =IF($A9="","",IF(IF(OR(O9="超期未收汇",O9="超过收汇期限仍未销售")," 收汇超期","")&IF(S9="已逾期"," 核算逾期","")&IF(S9="临近截止"," 核算临近截止","")&IF(LEFT(T9,1)="缺"," 单证"&T9,"")&IF(T9="未登记"," 单证未登记","")&IF(AND(ISNUMBER(G9),N(G9)<>0)," 入仓差异"&G9,"")="","正常",SUBSTITUTE(TRIM(IF(OR(O9="超期未收汇",O9="超过收汇期限仍未销售")," 收汇超期","")&IF(S9="已逾期"," 核算逾期","")&IF(S9="临近截止"," 核算临近截止","")&IF(LEFT(T9,1)="缺"," 单证"&T9,"")&IF(T9="未登记"," 单证未登记","")&IF(AND(ISNUMBER(G9),N(G9)<>0)," 入仓差异"&G9,""))," ","、")))
A10: =IF(①出口报关!A7="","",①出口报关!A7) | B10: =IF($A10="","",①出口报关!I7) | C10: =IF($A10="","",①出口报关!J7) | D10: =IF($A10="","",IF(①出口报关!D7="","",①出口报关!D7)) | E10: =IF($A10="","",N(①出口报关!L7)) | F10: =IF($A10="","",IF(①出口报关!Y7="","未签收",①出口报关!Y7)) | G10: =IF(OR($A10="",NOT(ISNUMBER(F10))),"",F10-E10) | H10: =IF($A10="","",SUMIFS(②销售核销!$I$4:$I$603,②销售核销!$E$4:$E$603,$A10)) | I10: =IF($A10="","",SUMIFS(⑤库存异常!$E$4:$E$203,⑤库存异常!$B$4:$B$203,$A10)) | J10: =IF($A10="","",IF(ISNUMBER(F10),F10,E10)-H10-I10) | K10: =IF(OR($A10="",N(E10)=0),"",H10/E10) | L10: =IF($A10="","",SUMIFS(②销售核销!$L$4:$L$603,②销售核销!$E$4:$E$603,$A10)) | M10: =IF($A10="","",SUMIFS(②销售核销!$L$4:$L$603,②销售核销!$E$4:$E$603,$A10,②销售核销!$M$4:$M$603,"已收汇")) | N10: =IF(ISNUMBER(D10),DATE(YEAR(D10)+1,4,30),"") | O10: =IF($A10="","",IF(N(H10)=0,IF(AND(ISNUMBER(N10),TODAY()>N10),"超过收汇期限仍未销售","尚未销售"),IF(ROUND(M10,2)>=ROUND(L10,2),"已售部分已收汇",IF(AND(ISNUMBER(N10),TODAY()>N10),"超期未收汇","有回款待收汇")))) | P10: =IF($A10="","",SUMIFS(④退税核算!$H$4:$H$303,④退税核算!$A$4:$A$303,$A10)) | Q10: =IF($A10="","",SUMIFS(④退税核算!$H$4:$H$303,④退税核算!$A$4:$A$303,$A10,④退税核算!$D$4:$D$303,"未售-海外仓预退（HWC-YT）")) | R10: =IF($A10="","",IF(COUNTIFS(④退税核算!$A$4:$A$303,$A10,④退税核算!$D$4:$D$303,"未售-海外仓预退（HWC-YT）",④退税核算!$I$4:$I$303,">0")=0,"",_xlfn.MINIFS(④退税核算!$J$4:$J$303,④退税核算!$A$4:$A$303,$A10,④退税核算!$D$4:$D$303,"未售-海外仓预退（HWC-YT）"))) | S10: =IF($A10="","",IF(COUNTIFS(④退税核算!$A$4:$A$303,$A10,④退税核算!$D$4:$D$303,"未售-海外仓预退（HWC-YT）")=0,"不涉及",IF(COUNTIFS(④退税核算!$A$4:$A$303,$A10,④退税核算!$S$4:$S$303,"已逾期*")>0,"已逾期",IF(COUNTIFS(④退税核算!$A$4:$A$303,$A10,④退税核算!$S$4:$S$303,"临近*")>0,"临近截止",IF(COUNTIFS(④退税核算!$A$4:$A$303,$A10,④退税核算!$S$4:$S$303,"待*")>0,"待核算","已核算"))))) | T10: =IF($A10="","",IFERROR(INDEX(⑥单证留存!$P$4:$P$203,MATCH(①出口报关!B7,⑥单证留存!$A$4:$A$203,0)),"未登记")) | U10: =IF($A10="","",IF(IF(OR(O10="超期未收汇",O10="超过收汇期限仍未销售")," 收汇超期","")&IF(S10="已逾期"," 核算逾期","")&IF(S10="临近截止"," 核算临近截止","")&IF(LEFT(T10,1)="缺"," 单证"&T10,"")&IF(T10="未登记"," 单证未登记","")&IF(AND(ISNUMBER(G10),N(G10)<>0)," 入仓差异"&G10,"")="","正常",SUBSTITUTE(TRIM(IF(OR(O10="超期未收汇",O10="超过收汇期限仍未销售")," 收汇超期","")&IF(S10="已逾期"," 核算逾期","")&IF(S10="临近截止"," 核算临近截止","")&IF(LEFT(T10,1)="缺"," 单证"&T10,"")&IF(T10="未登记"," 单证未登记","")&IF(AND(ISNUMBER(G10),N(G10)<>0)," 入仓差异"&G10,""))," ","、")))
A11: =IF(①出口报关!A8="","",①出口报关!A8) | B11: =IF($A11="","",①出口报关!I8) | C11: =IF($A11="","",①出口报关!J8) | D11: =IF($A11="","",IF(①出口报关!D8="","",①出口报关!D8)) | E11: =IF($A11="","",N(①出口报关!L8)) | F11: =IF($A11="","",IF(①出口报关!Y8="","未签收",①出口报关!Y8)) | G11: =IF(OR($A11="",NOT(ISNUMBER(F11))),"",F11-E11) | H11: =IF($A11="","",SUMIFS(②销售核销!$I$4:$I$603,②销售核销!$E$4:$E$603,$A11)) | I11: =IF($A11="","",SUMIFS(⑤库存异常!$E$4:$E$203,⑤库存异常!$B$4:$B$203,$A11)) | J11: =IF($A11="","",IF(ISNUMBER(F11),F11,E11)-H11-I11) | K11: =IF(OR($A11="",N(E11)=0),"",H11/E11) | L11: =IF($A11="","",SUMIFS(②销售核销!$L$4:$L$603,②销售核销!$E$4:$E$603,$A11)) | M11: =IF($A11="","",SUMIFS(②销售核销!$L$4:$L$603,②销售核销!$E$4:$E$603,$A11,②销售核销!$M$4:$M$603,"已收汇")) | N11: =IF(ISNUMBER(D11),DATE(YEAR(D11)+1,4,30),"") | O11: =IF($A11="","",IF(N(H11)=0,IF(AND(ISNUMBER(N11),TODAY()>N11),"超过收汇期限仍未销售","尚未销售"),IF(ROUND(M11,2)>=ROUND(L11,2),"已售部分已收汇",IF(AND(ISNUMBER(N11),TODAY()>N11),"超期未收汇","有回款待收汇")))) | P11: =IF($A11="","",SUMIFS(④退税核算!$H$4:$H$303,④退税核算!$A$4:$A$303,$A11)) | Q11: =IF($A11="","",SUMIFS(④退税核算!$H$4:$H$303,④退税核算!$A$4:$A$303,$A11,④退税核算!$D$4:$D$303,"未售-海外仓预退（HWC-YT）")) | R11: =IF($A11="","",IF(COUNTIFS(④退税核算!$A$4:$A$303,$A11,④退税核算!$D$4:$D$303,"未售-海外仓预退（HWC-YT）",④退税核算!$I$4:$I$303,">0")=0,"",_xlfn.MINIFS(④退税核算!$J$4:$J$303,④退税核算!$A$4:$A$303,$A11,④退税核算!$D$4:$D$303,"未售-海外仓预退（HWC-YT）"))) | S11: =IF($A11="","",IF(COUNTIFS(④退税核算!$A$4:$A$303,$A11,④退税核算!$D$4:$D$303,"未售-海外仓预退（HWC-YT）")=0,"不涉及",IF(COUNTIFS(④退税核算!$A$4:$A$303,$A11,④退税核算!$S$4:$S$303,"已逾期*")>0,"已逾期",IF(COUNTIFS(④退税核算!$A$4:$A$303,$A11,④退税核算!$S$4:$S$303,"临近*")>0,"临近截止",IF(COUNTIFS(④退税核算!$A$4:$A$303,$A11,④退税核算!$S$4:$S$303,"待*")>0,"待核算","已核算"))))) | T11: =IF($A11="","",IFERROR(INDEX(⑥单证留存!$P$4:$P$203,MATCH(①出口报关!B8,⑥单证留存!$A$4:$A$203,0)),"未登记")) | U11: =IF($A11="","",IF(IF(OR(O11="超期未收汇",O11="超过收汇期限仍未销售")," 收汇超期","")&IF(S11="已逾期"," 核算逾期","")&IF(S11="临近截止"," 核算临近截止","")&IF(LEFT(T11,1)="缺"," 单证"&T11,"")&IF(T11="未登记"," 单证未登记","")&IF(AND(ISNUMBER(G11),N(G11)<>0)," 入仓差异"&G11,"")="","正常",SUBSTITUTE(TRIM(IF(OR(O11="超期未收汇",O11="超过收汇期限仍未销售")," 收汇超期","")&IF(S11="已逾期"," 核算逾期","")&IF(S11="临近截止"," 核算临近截止","")&IF(LEFT(T11,1)="缺"," 单证"&T11,"")&IF(T11="未登记"," 单证未登记","")&IF(AND(ISNUMBER(G11),N(G11)<>0)," 入仓差异"&G11,""))," ","、")))
A12: =IF(①出口报关!A9="","",①出口报关!A9) | B12: =IF($A12="","",①出口报关!I9) | C12: =IF($A12="","",①出口报关!J9) | D12: =IF($A12="","",IF(①出口报关!D9="","",①出口报关!D9)) | E12: =IF($A12="","",N(①出口报关!L9)) | F12: =IF($A12="","",IF(①出口报关!Y9="","未签收",①出口报关!Y9)) | G12: =IF(OR($A12="",NOT(ISNUMBER(F12))),"",F12-E12) | H12: =IF($A12="","",SUMIFS(②销售核销!$I$4:$I$603,②销售核销!$E$4:$E$603,$A12)) | I12: =IF($A12="","",SUMIFS(⑤库存异常!$E$4:$E$203,⑤库存异常!$B$4:$B$203,$A12)) | J12: =IF($A12="","",IF(ISNUMBER(F12),F12,E12)-H12-I12) | K12: =IF(OR($A12="",N(E12)=0),"",H12/E12) | L12: =IF($A12="","",SUMIFS(②销售核销!$L$4:$L$603,②销售核销!$E$4:$E$603,$A12)) | M12: =IF($A12="","",SUMIFS(②销售核销!$L$4:$L$603,②销售核销!$E$4:$E$603,$A12,②销售核销!$M$4:$M$603,"已收汇")) | N12: =IF(ISNUMBER(D12),DATE(YEAR(D12)+1,4,30),"") | O12: =IF($A12="","",IF(N(H12)=0,IF(AND(ISNUMBER(N12),TODAY()>N12),"超过收汇期限仍未销售","尚未销售"),IF(ROUND(M12,2)>=ROUND(L12,2),"已售部分已收汇",IF(AND(ISNUMBER(N12),TODAY()>N12),"超期未收汇","有回款待收汇")))) | P12: =IF($A12="","",SUMIFS(④退税核算!$H$4:$H$303,④退税核算!$A$4:$A$303,$A12)) | Q12: =IF($A12="","",SUMIFS(④退税核算!$H$4:$H$303,④退税核算!$A$4:$A$303,$A12,④退税核算!$D$4:$D$303,"未售-海外仓预退（HWC-YT）")) | R12: =IF($A12="","",IF(COUNTIFS(④退税核算!$A$4:$A$303,$A12,④退税核算!$D$4:$D$303,"未售-海外仓预退（HWC-YT）",④退税核算!$I$4:$I$303,">0")=0,"",_xlfn.MINIFS(④退税核算!$J$4:$J$303,④退税核算!$A$4:$A$303,$A12,④退税核算!$D$4:$D$303,"未售-海外仓预退（HWC-YT）"))) | S12: =IF($A12="","",IF(COUNTIFS(④退税核算!$A$4:$A$303,$A12,④退税核算!$D$4:$D$303,"未售-海外仓预退（HWC-YT）")=0,"不涉及",IF(COUNTIFS(④退税核算!$A$4:$A$303,$A12,④退税核算!$S$4:$S$303,"已逾期*")>0,"已逾期",IF(COUNTIFS(④退税核算!$A$4:$A$303,$A12,④退税核算!$S$4:$S$303,"临近*")>0,"临近截止",IF(COUNTIFS(④退税核算!$A$4:$A$303,$A12,④退税核算!$S$4:$S$303,"待*")>0,"待核算","已核算"))))) | T12: =IF($A12="","",IFERROR(INDEX(⑥单证留存!$P$4:$P$203,MATCH(①出口报关!B9,⑥单证留存!$A$4:$A$203,0)),"未登记")) | U12: =IF($A12="","",IF(IF(OR(O12="超期未收汇",O12="超过收汇期限仍未销售")," 收汇超期","")&IF(S12="已逾期"," 核算逾期","")&IF(S12="临近截止"," 核算临近截止","")&IF(LEFT(T12,1)="缺"," 单证"&T12,"")&IF(T12="未登记"," 单证未登记","")&IF(AND(ISNUMBER(G12),N(G12)<>0)," 入仓差异"&G12,"")="","正常",SUBSTITUTE(TRIM(IF(OR(O12="超期未收汇",O12="超过收汇期限仍未销售")," 收汇超期","")&IF(S12="已逾期"," 核算逾期","")&IF(S12="临近截止"," 核算临近截止","")&IF(LEFT(T12,1)="缺"," 单证"&T12,"")&IF(T12="未登记"," 单证未登记","")&IF(AND(ISNUMBER(G12),N(G12)<>0)," 入仓差异"&G12,""))," ","、")))
A13: =IF(①出口报关!A10="","",①出口报关!A10) | B13: =IF($A13="","",①出口报关!I10) | C13: =IF($A13="","",①出口报关!J10) | D13: =IF($A13="","",IF(①出口报关!D10="","",①出口报关!D10)) | E13: =IF($A13="","",N(①出口报关!L10)) | F13: =IF($A13="","",IF(①出口报关!Y10="","未签收",①出口报关!Y10)) | G13: =IF(OR($A13="",NOT(ISNUMBER(F13))),"",F13-E13) | H13: =IF($A13="","",SUMIFS(②销售核销!$I$4:$I$603,②销售核销!$E$4:$E$603,$A13)) | I13: =IF($A13="","",SUMIFS(⑤库存异常!$E$4:$E$203,⑤库存异常!$B$4:$B$203,$A13)) | J13: =IF($A13="","",IF(ISNUMBER(F13),F13,E13)-H13-I13) | K13: =IF(OR($A13="",N(E13)=0),"",H13/E13) | L13: =IF($A13="","",SUMIFS(②销售核销!$L$4:$L$603,②销售核销!$E$4:$E$603,$A13)) | M13: =IF($A13="","",SUMIFS(②销售核销!$L$4:$L$603,②销售核销!$E$4:$E$603,$A13,②销售核销!$M$4:$M$603,"已收汇")) | N13: =IF(ISNUMBER(D13),DATE(YEAR(D13)+1,4,30),"") | O13: =IF($A13="","",IF(N(H13)=0,IF(AND(ISNUMBER(N13),TODAY()>N13),"超过收汇期限仍未销售","尚未销售"),IF(ROUND(M13,2)>=ROUND(L13,2),"已售部分已收汇",IF(AND(ISNUMBER(N13),TODAY()>N13),"超期未收汇","有回款待收汇")))) | P13: =IF($A13="","",SUMIFS(④退税核算!$H$4:$H$303,④退税核算!$A$4:$A$303,$A13)) | Q13: =IF($A13="","",SUMIFS(④退税核算!$H$4:$H$303,④退税核算!$A$4:$A$303,$A13,④退税核算!$D$4:$D$303,"未售-海外仓预退（HWC-YT）")) | R13: =IF($A13="","",IF(COUNTIFS(④退税核算!$A$4:$A$303,$A13,④退税核算!$D$4:$D$303,"未售-海外仓预退（HWC-YT）",④退税核算!$I$4:$I$303,">0")=0,"",_xlfn.MINIFS(④退税核算!$J$4:$J$303,④退税核算!$A$4:$A$303,$A13,④退税核算!$D$4:$D$303,"未售-海外仓预退（HWC-YT）"))) | S13: =IF($A13="","",IF(COUNTIFS(④退税核算!$A$4:$A$303,$A13,④退税核算!$D$4:$D$303,"未售-海外仓预退（HWC-YT）")=0,"不涉及",IF(COUNTIFS(④退税核算!$A$4:$A$303,$A13,④退税核算!$S$4:$S$303,"已逾期*")>0,"已逾期",IF(COUNTIFS(④退税核算!$A$4:$A$303,$A13,④退税核算!$S$4:$S$303,"临近*")>0,"临近截止",IF(COUNTIFS(④退税核算!$A$4:$A$303,$A13,④退税核算!$S$4:$S$303,"待*")>0,"待核算","已核算"))))) | T13: =IF($A13="","",IFERROR(INDEX(⑥单证留存!$P$4:$P$203,MATCH(①出口报关!B10,⑥单证留存!$A$4:$A$203,0)),"未登记")) | U13: =IF($A13="","",IF(IF(OR(O13="超期未收汇",O13="超过收汇期限仍未销售")," 收汇超期","")&IF(S13="已逾期"," 核算逾期","")&IF(S13="临近截止"," 核算临近截止","")&IF(LEFT(T13,1)="缺"," 单证"&T13,"")&IF(T13="未登记"," 单证未登记","")&IF(AND(ISNUMBER(G13),N(G13)<>0)," 入仓差异"&G13,"")="","正常",SUBSTITUTE(TRIM(IF(OR(O13="超期未收汇",O13="超过收汇期限仍未销售")," 收汇超期","")&IF(S13="已逾期"," 核算逾期","")&IF(S13="临近截止"," 核算临近截止","")&IF(LEFT(T13,1)="缺"," 单证"&T13,"")&IF(T13="未登记"," 单证未登记","")&IF(AND(ISNUMBER(G13),N(G13)<>0)," 入仓差异"&G13,""))," ","、")))
A14: =IF(①出口报关!A11="","",①出口报关!A11) | B14: =IF($A14="","",①出口报关!I11) | C14: =IF($A14="","",①出口报关!J11) | D14: =IF($A14="","",IF(①出口报关!D11="","",①出口报关!D11)) | E14: =IF($A14="","",N(①出口报关!L11)) | F14: =IF($A14="","",IF(①出口报关!Y11="","未签收",①出口报关!Y11)) | G14: =IF(OR($A14="",NOT(ISNUMBER(F14))),"",F14-E14) | H14: =IF($A14="","",SUMIFS(②销售核销!$I$4:$I$603,②销售核销!$E$4:$E$603,$A14)) | I14: =IF($A14="","",SUMIFS(⑤库存异常!$E$4:$E$203,⑤库存异常!$B$4:$B$203,$A14)) | J14: =IF($A14="","",IF(ISNUMBER(F14),F14,E14)-H14-I14) | K14: =IF(OR($A14="",N(E14)=0),"",H14/E14) | L14: =IF($A14="","",SUMIFS(②销售核销!$L$4:$L$603,②销售核销!$E$4:$E$603,$A14)) | M14: =IF($A14="","",SUMIFS(②销售核销!$L$4:$L$603,②销售核销!$E$4:$E$603,$A14,②销售核销!$M$4:$M$603,"已收汇")) | N14: =IF(ISNUMBER(D14),DATE(YEAR(D14)+1,4,30),"") | O14: =IF($A14="","",IF(N(H14)=0,IF(AND(ISNUMBER(N14),TODAY()>N14),"超过收汇期限仍未销售","尚未销售"),IF(ROUND(M14,2)>=ROUND(L14,2),"已售部分已收汇",IF(AND(ISNUMBER(N14),TODAY()>N14),"超期未收汇","有回款待收汇")))) | P14: =IF($A14="","",SUMIFS(④退税核算!$H$4:$H$303,④退税核算!$A$4:$A$303,$A14)) | Q14: =IF($A14="","",SUMIFS(④退税核算!$H$4:$H$303,④退税核算!$A$4:$A$303,$A14,④退税核算!$D$4:$D$303,"未售-海外仓预退（HWC-YT）")) | R14: =IF($A14="","",IF(COUNTIFS(④退税核算!$A$4:$A$303,$A14,④退税核算!$D$4:$D$303,"未售-海外仓预退（HWC-YT）",④退税核算!$I$4:$I$303,">0")=0,"",_xlfn.MINIFS(④退税核算!$J$4:$J$303,④退税核算!$A$4:$A$303,$A14,④退税核算!$D$4:$D$303,"未售-海外仓预退（HWC-YT）"))) | S14: =IF($A14="","",IF(COUNTIFS(④退税核算!$A$4:$A$303,$A14,④退税核算!$D$4:$D$303,"未售-海外仓预退（HWC-YT）")=0,"不涉及",IF(COUNTIFS(④退税核算!$A$4:$A$303,$A14,④退税核算!$S$4:$S$303,"已逾期*")>0,"已逾期",IF(COUNTIFS(④退税核算!$A$4:$A$303,$A14,④退税核算!$S$4:$S$303,"临近*")>0,"临近截止",IF(COUNTIFS(④退税核算!$A$4:$A$303,$A14,④退税核算!$S$4:$S$303,"待*")>0,"待核算","已核算"))))) | T14: =IF($A14="","",IFERROR(INDEX(⑥单证留存!$P$4:$P$203,MATCH(①出口报关!B11,⑥单证留存!$A$4:$A$203,0)),"未登记")) | U14: =IF($A14="","",IF(IF(OR(O14="超期未收汇",O14="超过收汇期限仍未销售")," 收汇超期","")&IF(S14="已逾期"," 核算逾期","")&IF(S14="临近截止"," 核算临近截止","")&IF(LEFT(T14,1)="缺"," 单证"&T14,"")&IF(T14="未登记"," 单证未登记","")&IF(AND(ISNUMBER(G14),N(G14)<>0)," 入仓差异"&G14,"")="","正常",SUBSTITUTE(TRIM(IF(OR(O14="超期未收汇",O14="超过收汇期限仍未销售")," 收汇超期","")&IF(S14="已逾期"," 核算逾期","")&IF(S14="临近截止"," 核算临近截止","")&IF(LEFT(T14,1)="缺"," 单证"&T14,"")&IF(T14="未登记"," 单证未登记","")&IF(AND(ISNUMBER(G14),N(G14)<>0)," 入仓差异"&G14,""))," ","、")))
A15: =IF(①出口报关!A12="","",①出口报关!A12) | B15: =IF($A15="","",①出口报关!I12) | C15: =IF($A15="","",①出口报关!J12) | D15: =IF($A15="","",IF(①出口报关!D12="","",①出口报关!D12)) | E15: =IF($A15="","",N(①出口报关!L12)) | F15: =IF($A15="","",IF(①出口报关!Y12="","未签收",①出口报关!Y12)) | G15: =IF(OR($A15="",NOT(ISNUMBER(F15))),"",F15-E15) | H15: =IF($A15="","",SUMIFS(②销售核销!$I$4:$I$603,②销售核销!$E$4:$E$603,$A15)) | I15: =IF($A15="","",SUMIFS(⑤库存异常!$E$4:$E$203,⑤库存异常!$B$4:$B$203,$A15)) | J15: =IF($A15="","",IF(ISNUMBER(F15),F15,E15)-H15-I15) | K15: =IF(OR($A15="",N(E15)=0),"",H15/E15) | L15: =IF($A15="","",SUMIFS(②销售核销!$L$4:$L$603,②销售核销!$E$4:$E$603,$A15)) | M15: =IF($A15="","",SUMIFS(②销售核销!$L$4:$L$603,②销售核销!$E$4:$E$603,$A15,②销售核销!$M$4:$M$603,"已收汇")) | N15: =IF(ISNUMBER(D15),DATE(YEAR(D15)+1,4,30),"") | O15: =IF($A15="","",IF(N(H15)=0,IF(AND(ISNUMBER(N15),TODAY()>N15),"超过收汇期限仍未销售","尚未销售"),IF(ROUND(M15,2)>=ROUND(L15,2),"已售部分已收汇",IF(AND(ISNUMBER(N15),TODAY()>N15),"超期未收汇","有回款待收汇")))) | P15: =IF($A15="","",SUMIFS(④退税核算!$H$4:$H$303,④退税核算!$A$4:$A$303,$A15)) | Q15: =IF($A15="","",SUMIFS(④退税核算!$H$4:$H$303,④退税核算!$A$4:$A$303,$A15,④退税核算!$D$4:$D$303,"未售-海外仓预退（HWC-YT）")) | R15: =IF($A15="","",IF(COUNTIFS(④退税核算!$A$4:$A$303,$A15,④退税核算!$D$4:$D$303,"未售-海外仓预退（HWC-YT）",④退税核算!$I$4:$I$303,">0")=0,"",_xlfn.MINIFS(④退税核算!$J$4:$J$303,④退税核算!$A$4:$A$303,$A15,④退税核算!$D$4:$D$303,"未售-海外仓预退（HWC-YT）"))) | S15: =IF($A15="","",IF(COUNTIFS(④退税核算!$A$4:$A$303,$A15,④退税核算!$D$4:$D$303,"未售-海外仓预退（HWC-YT）")=0,"不涉及",IF(COUNTIFS(④退税核算!$A$4:$A$303,$A15,④退税核算!$S$4:$S$303,"已逾期*")>0,"已逾期",IF(COUNTIFS(④退税核算!$A$4:$A$303,$A15,④退税核算!$S$4:$S$303,"临近*")>0,"临近截止",IF(COUNTIFS(④退税核算!$A$4:$A$303,$A15,④退税核算!$S$4:$S$303,"待*")>0,"待核算","已核算"))))) | T15: =IF($A15="","",IFERROR(INDEX(⑥单证留存!$P$4:$P$203,MATCH(①出口报关!B12,⑥单证留存!$A$4:$A$203,0)),"未登记")) | U15: =IF($A15="","",IF(IF(OR(O15="超期未收汇",O15="超过收汇期限仍未销售")," 收汇超期","")&IF(S15="已逾期"," 核算逾期","")&IF(S15="临近截止"," 核算临近截止","")&IF(LEFT(T15,1)="缺"," 单证"&T15,"")&IF(T15="未登记"," 单证未登记","")&IF(AND(ISNUMBER(G15),N(G15)<>0)," 入仓差异"&G15,"")="","正常",SUBSTITUTE(TRIM(IF(OR(O15="超期未收汇",O15="超过收汇期限仍未销售")," 收汇超期","")&IF(S15="已逾期"," 核算逾期","")&IF(S15="临近截止"," 核算临近截止","")&IF(LEFT(T15,1)="缺"," 单证"&T15,"")&IF(T15="未登记"," 单证未登记","")&IF(AND(ISNUMBER(G15),N(G15)<>0)," 入仓差异"&G15,""))," ","、")))
A16: =IF(①出口报关!A13="","",①出口报关!A13) | B16: =IF($A16="","",①出口报关!I13) | C16: =IF($A16="","",①出口报关!J13) | D16: =IF($A16="","",IF(①出口报关!D13="","",①出口报关!D13)) | E16: =IF($A16="","",N(①出口报关!L13)) | F16: =IF($A16="","",IF(①出口报关!Y13="","未签收",①出口报关!Y13)) | G16: =IF(OR($A16="",NOT(ISNUMBER(F16))),"",F16-E16) | H16: =IF($A16="","",SUMIFS(②销售核销!$I$4:$I$603,②销售核销!$E$4:$E$603,$A16)) | I16: =IF($A16="","",SUMIFS(⑤库存异常!$E$4:$E$203,⑤库存异常!$B$4:$B$203,$A16)) | J16: =IF($A16="","",IF(ISNUMBER(F16),F16,E16)-H16-I16) | K16: =IF(OR($A16="",N(E16)=0),"",H16/E16) | L16: =IF($A16="","",SUMIFS(②销售核销!$L$4:$L$603,②销售核销!$E$4:$E$603,$A16)) | M16: =IF($A16="","",SUMIFS(②销售核销!$L$4:$L$603,②销售核销!$E$4:$E$603,$A16,②销售核销!$M$4:$M$603,"已收汇")) | N16: =IF(ISNUMBER(D16),DATE(YEAR(D16)+1,4,30),"") | O16: =IF($A16="","",IF(N(H16)=0,IF(AND(ISNUMBER(N16),TODAY()>N16),"超过收汇期限仍未销售","尚未销售"),IF(ROUND(M16,2)>=ROUND(L16,2),"已售部分已收汇",IF(AND(ISNUMBER(N16),TODAY()>N16),"超期未收汇","有回款待收汇")))) | P16: =IF($A16="","",SUMIFS(④退税核算!$H$4:$H$303,④退税核算!$A$4:$A$303,$A16)) | Q16: =IF($A16="","",SUMIFS(④退税核算!$H$4:$H$303,④退税核算!$A$4:$A$303,$A16,④退税核算!$D$4:$D$303,"未售-海外仓预退（HWC-YT）")) | R16: =IF($A16="","",IF(COUNTIFS(④退税核算!$A$4:$A$303,$A16,④退税核算!$D$4:$D$303,"未售-海外仓预退（HWC-YT）",④退税核算!$I$4:$I$303,">0")=0,"",_xlfn.MINIFS(④退税核算!$J$4:$J$303,④退税核算!$A$4:$A$303,$A16,④退税核算!$D$4:$D$303,"未售-海外仓预退（HWC-YT）"))) | S16: =IF($A16="","",IF(COUNTIFS(④退税核算!$A$4:$A$303,$A16,④退税核算!$D$4:$D$303,"未售-海外仓预退（HWC-YT）")=0,"不涉及",IF(COUNTIFS(④退税核算!$A$4:$A$303,$A16,④退税核算!$S$4:$S$303,"已逾期*")>0,"已逾期",IF(COUNTIFS(④退税核算!$A$4:$A$303,$A16,④退税核算!$S$4:$S$303,"临近*")>0,"临近截止",IF(COUNTIFS(④退税核算!$A$4:$A$303,$A16,④退税核算!$S$4:$S$303,"待*")>0,"待核算","已核算"))))) | T16: =IF($A16="","",IFERROR(INDEX(⑥单证留存!$P$4:$P$203,MATCH(①出口报关!B13,⑥单证留存!$A$4:$A$203,0)),"未登记")) | U16: =IF($A16="","",IF(IF(OR(O16="超期未收汇",O16="超过收汇期限仍未销售")," 收汇超期","")&IF(S16="已逾期"," 核算逾期","")&IF(S16="临近截止"," 核算临近截止","")&IF(LEFT(T16,1)="缺"," 单证"&T16,"")&IF(T16="未登记"," 单证未登记","")&IF(AND(ISNUMBER(G16),N(G16)<>0)," 入仓差异"&G16,"")="","正常",SUBSTITUTE(TRIM(IF(OR(O16="超期未收汇",O16="超过收汇期限仍未销售")," 收汇超期","")&IF(S16="已逾期"," 核算逾期","")&IF(S16="临近截止"," 核算临近截止","")&IF(LEFT(T16,1)="缺"," 单证"&T16,"")&IF(T16="未登记"," 单证未登记","")&IF(AND(ISNUMBER(G16),N(G16)<>0)," 入仓差异"&G16,""))," ","、")))
A17: =IF(①出口报关!A14="","",①出口报关!A14) | B17: =IF($A17="","",①出口报关!I14) | C17: =IF($A17="","",①出口报关!J14) | D17: =IF($A17="","",IF(①出口报关!D14="","",①出口报关!D14)) | E17: =IF($A17="","",N(①出口报关!L14)) | F17: =IF($A17="","",IF(①出口报关!Y14="","未签收",①出口报关!Y14)) | G17: =IF(OR($A17="",NOT(ISNUMBER(F17))),"",F17-E17) | H17: =IF($A17="","",SUMIFS(②销售核销!$I$4:$I$603,②销售核销!$E$4:$E$603,$A17)) | I17: =IF($A17="","",SUMIFS(⑤库存异常!$E$4:$E$203,⑤库存异常!$B$4:$B$203,$A17)) | J17: =IF($A17="","",IF(ISNUMBER(F17),F17,E17)-H17-I17) | K17: =IF(OR($A17="",N(E17)=0),"",H17/E17) | L17: =IF($A17="","",SUMIFS(②销售核销!$L$4:$L$603,②销售核销!$E$4:$E$603,$A17)) | M17: =IF($A17="","",SUMIFS(②销售核销!$L$4:$L$603,②销售核销!$E$4:$E$603,$A17,②销售核销!$M$4:$M$603,"已收汇")) | N17: =IF(ISNUMBER(D17),DATE(YEAR(D17)+1,4,30),"") | O17: =IF($A17="","",IF(N(H17)=0,IF(AND(ISNUMBER(N17),TODAY()>N17),"超过收汇期限仍未销售","尚未销售"),IF(ROUND(M17,2)>=ROUND(L17,2),"已售部分已收汇",IF(AND(ISNUMBER(N17),TODAY()>N17),"超期未收汇","有回款待收汇")))) | P17: =IF($A17="","",SUMIFS(④退税核算!$H$4:$H$303,④退税核算!$A$4:$A$303,$A17)) | Q17: =IF($A17="","",SUMIFS(④退税核算!$H$4:$H$303,④退税核算!$A$4:$A$303,$A17,④退税核算!$D$4:$D$303,"未售-海外仓预退（HWC-YT）")) | R17: =IF($A17="","",IF(COUNTIFS(④退税核算!$A$4:$A$303,$A17,④退税核算!$D$4:$D$303,"未售-海外仓预退（HWC-YT）",④退税核算!$I$4:$I$303,">0")=0,"",_xlfn.MINIFS(④退税核算!$J$4:$J$303,④退税核算!$A$4:$A$303,$A17,④退税核算!$D$4:$D$303,"未售-海外仓预退（HWC-YT）"))) | S17: =IF($A17="","",IF(COUNTIFS(④退税核算!$A$4:$A$303,$A17,④退税核算!$D$4:$D$303,"未售-海外仓预退（HWC-YT）")=0,"不涉及",IF(COUNTIFS(④退税核算!$A$4:$A$303,$A17,④退税核算!$S$4:$S$303,"已逾期*")>0,"已逾期",IF(COUNTIFS(④退税核算!$A$4:$A$303,$A17,④退税核算!$S$4:$S$303,"临近*")>0,"临近截止",IF(COUNTIFS(④退税核算!$A$4:$A$303,$A17,④退税核算!$S$4:$S$303,"待*")>0,"待核算","已核算"))))) | T17: =IF($A17="","",IFERROR(INDEX(⑥单证留存!$P$4:$P$203,MATCH(①出口报关!B14,⑥单证留存!$A$4:$A$203,0)),"未登记")) | U17: =IF($A17="","",IF(IF(OR(O17="超期未收汇",O17="超过收汇期限仍未销售")," 收汇超期","")&IF(S17="已逾期"," 核算逾期","")&IF(S17="临近截止"," 核算临近截止","")&IF(LEFT(T17,1)="缺"," 单证"&T17,"")&IF(T17="未登记"," 单证未登记","")&IF(AND(ISNUMBER(G17),N(G17)<>0)," 入仓差异"&G17,"")="","正常",SUBSTITUTE(TRIM(IF(OR(O17="超期未收汇",O17="超过收汇期限仍未销售")," 收汇超期","")&IF(S17="已逾期"," 核算逾期","")&IF(S17="临近截止"," 核算临近截止","")&IF(LEFT(T17,1)="缺"," 单证"&T17,"")&IF(T17="未登记"," 单证未登记","")&IF(AND(ISNUMBER(G17),N(G17)<>0)," 入仓差异"&G17,""))," ","、")))
A18: =IF(①出口报关!A15="","",①出口报关!A15) | B18: =IF($A18="","",①出口报关!I15) | C18: =IF($A18="","",①出口报关!J15) | D18: =IF($A18="","",IF(①出口报关!D15="","",①出口报关!D15)) | E18: =IF($A18="","",N(①出口报关!L15)) | F18: =IF($A18="","",IF(①出口报关!Y15="","未签收",①出口报关!Y15)) | G18: =IF(OR($A18="",NOT(ISNUMBER(F18))),"",F18-E18) | H18: =IF($A18="","",SUMIFS(②销售核销!$I$4:$I$603,②销售核销!$E$4:$E$603,$A18)) | I18: =IF($A18="","",SUMIFS(⑤库存异常!$E$4:$E$203,⑤库存异常!$B$4:$B$203,$A18)) | J18: =IF($A18="","",IF(ISNUMBER(F18),F18,E18)-H18-I18) | K18: =IF(OR($A18="",N(E18)=0),"",H18/E18) | L18: =IF($A18="","",SUMIFS(②销售核销!$L$4:$L$603,②销售核销!$E$4:$E$603,$A18)) | M18: =IF($A18="","",SUMIFS(②销售核销!$L$4:$L$603,②销售核销!$E$4:$E$603,$A18,②销售核销!$M$4:$M$603,"已收汇")) | N18: =IF(ISNUMBER(D18),DATE(YEAR(D18)+1,4,30),"") | O18: =IF($A18="","",IF(N(H18)=0,IF(AND(ISNUMBER(N18),TODAY()>N18),"超过收汇期限仍未销售","尚未销售"),IF(ROUND(M18,2)>=ROUND(L18,2),"已售部分已收汇",IF(AND(ISNUMBER(N18),TODAY()>N18),"超期未收汇","有回款待收汇")))) | P18: =IF($A18="","",SUMIFS(④退税核算!$H$4:$H$303,④退税核算!$A$4:$A$303,$A18)) | Q18: =IF($A18="","",SUMIFS(④退税核算!$H$4:$H$303,④退税核算!$A$4:$A$303,$A18,④退税核算!$D$4:$D$303,"未售-海外仓预退（HWC-YT）")) | R18: =IF($A18="","",IF(COUNTIFS(④退税核算!$A$4:$A$303,$A18,④退税核算!$D$4:$D$303,"未售-海外仓预退（HWC-YT）",④退税核算!$I$4:$I$303,">0")=0,"",_xlfn.MINIFS(④退税核算!$J$4:$J$303,④退税核算!$A$4:$A$303,$A18,④退税核算!$D$4:$D$303,"未售-海外仓预退（HWC-YT）"))) | S18: =IF($A18="","",IF(COUNTIFS(④退税核算!$A$4:$A$303,$A18,④退税核算!$D$4:$D$303,"未售-海外仓预退（HWC-YT）")=0,"不涉及",IF(COUNTIFS(④退税核算!$A$4:$A$303,$A18,④退税核算!$S$4:$S$303,"已逾期*")>0,"已逾期",IF(COUNTIFS(④退税核算!$A$4:$A$303,$A18,④退税核算!$S$4:$S$303,"临近*")>0,"临近截止",IF(COUNTIFS(④退税核算!$A$4:$A$303,$A18,④退税核算!$S$4:$S$303,"待*")>0,"待核算","已核算"))))) | T18: =IF($A18="","",IFERROR(INDEX(⑥单证留存!$P$4:$P$203,MATCH(①出口报关!B15,⑥单证留存!$A$4:$A$203,0)),"未登记")) | U18: =IF($A18="","",IF(IF(OR(O18="超期未收汇",O18="超过收汇期限仍未销售")," 收汇超期","")&IF(S18="已逾期"," 核算逾期","")&IF(S18="临近截止"," 核算临近截止","")&IF(LEFT(T18,1)="缺"," 单证"&T18,"")&IF(T18="未登记"," 单证未登记","")&IF(AND(ISNUMBER(G18),N(G18)<>0)," 入仓差异"&G18,"")="","正常",SUBSTITUTE(TRIM(IF(OR(O18="超期未收汇",O18="超过收汇期限仍未销售")," 收汇超期","")&IF(S18="已逾期"," 核算逾期","")&IF(S18="临近截止"," 核算临近截止","")&IF(LEFT(T18,1)="缺"," 单证"&T18,"")&IF(T18="未登记"," 单证未登记","")&IF(AND(ISNUMBER(G18),N(G18)<>0)," 入仓差异"&G18,""))," ","、")))
... A306: =IF(①出口报关!A303="","",①出口报关!A303) | B306: =IF($A306="","",①出口报关!I303) | C306: =IF($A306="","",①出口报关!J303) | D306: =IF($A306="","",IF(①出口报关!D303="","",①出口报关!D303)) | E306: =IF($A306="","",N(①出口报关!L303)) | F306: =IF($A306="","",IF(①出口报关!Y303="","未签收",①出口报关!Y303)) | G306: =IF(OR($A306="",NOT(ISNUMBER(F306))),"",F306-E306) | H306: =IF($A306="","",SUMIFS(②销售核销!$I$4:$I$603,②销售核销!$E$4:$E$603,$A306)) | I306: =IF($A306="","",SUMIFS(⑤库存异常!$E$4:$E$203,⑤库存异常!$B$4:$B$203,$A306)) | J306: =IF($A306="","",IF(ISNUMBER(F306),F306,E306)-H306-I306) | K306: =IF(OR($A306="",N(E306)=0),"",H306/E306) | L306: =IF($A306="","",SUMIFS(②销售核销!$L$4:$L$603,②销售核销!$E$4:$E$603,$A306)) | M306: =IF($A306="","",SUMIFS(②销售核销!$L$4:$L$603,②销售核销!$E$4:$E$603,$A306,②销售核销!$M$4:$M$603,"已收汇")) | N306: =IF(ISNUMBER(D306),DATE(YEAR(D306)+1,4,30),"") | O306: =IF($A306="","",IF(N(H306)=0,IF(AND(ISNUMBER(N306),TODAY()>N306),"超过收汇期限仍未销售","尚未销售"),IF(ROUND(M306,2)>=ROUND(L306,2),"已售部分已收汇",IF(AND(ISNUMBER(N306),TODAY()>N306),"超期未收汇","有回款待收汇")))) | P306: =IF($A306="","",SUMIFS(④退税核算!$H$4:$H$303,④退税核算!$A$4:$A$303,$A306)) | Q306: =IF($A306="","",SUMIFS(④退税核算!$H$4:$H$303,④退税核算!$A$4:$A$303,$A306,④退税核算!$D$4:$D$303,"未售-海外仓预退（HWC-YT）")) | R306: =IF($A306="","",IF(COUNTIFS(④退税核算!$A$4:$A$303,$A306,④退税核算!$D$4:$D$303,"未售-海外仓预退（HWC-YT）",④退税核算!$I$4:$I$303,">0")=0,"",_xlfn.MINIFS(④退税核算!$J$4:$J$303,④退税核算!$A$4:$A$303,$A306,④退税核算!$D$4:$D$303,"未售-海外仓预退（HWC-YT）"))) | S306: =IF($A306="","",IF(COUNTIFS(④退税核算!$A$4:$A$303,$A306,④退税核算!$D$4:$D$303,"未售-海外仓预退（HWC-YT）")=0,"不涉及",IF(COUNTIFS(④退税核算!$A$4:$A$303,$A306,④退税核算!$S$4:$S$303,"已逾期*")>0,"已逾期",IF(COUNTIFS(④退税核算!$A$4:$A$303,$A306,④退税核算!$S$4:$S$303,"临近*")>0,"临近截止",IF(COUNTIFS(④退税核算!$A$4:$A$303,$A306,④退税核算!$S$4:$S$303,"待*")>0,"待核算","已核算"))))) | T306: =IF($A306="","",IFERROR(INDEX(⑥单证留存!$P$4:$P$203,MATCH(①出口报关!B303,⑥单证留存!$A$4:$A$203,0)),"未登记")) | U306: =IF($A306="","",IF(IF(OR(O306="超期未收汇",O306="超过收汇期限仍未销售")," 收汇超期","")&IF(S306="已逾期"," 核算逾期","")&IF(S306="临近截止"," 核算临近截止","")&IF(LEFT(T306,1)="缺"," 单证"&T306,"")&IF(T306="未登记"," 单证未登记","")&IF(AND(ISNUMBER(G306),N(G306)<>0)," 入仓差异"&G306,"")="","正常",SUBSTITUTE(TRIM(IF(OR(O306="超期未收汇",O306="超过收汇期限仍未销售")," 收汇超期","")&IF(S306="已逾期"," 核算逾期","")&IF(S306="临近截止"," 核算临近截止","")&IF(LEFT(T306,1)="缺"," 单证"&T306,"")&IF(T306="未登记"," 单证未登记","")&IF(AND(ISNUMBER(G306),N(G306)<>0)," 入仓差异"&G306,""))," ","、")))

Sheet ①出口报关
A1: ① 出口报关（含亚马逊入仓签收）
A2: 每个报关单项号一行。白底格子手填，浅蓝色格子自动计算。签收数量取自亚马逊货件页面「已收到」数量。
A3: 核销编号（自动） | B3: 报关单号 | C3: 项号 | D3: 出口日期 | E3: 监管方式 | F3: FBA货件号（订仓单号） | G3: 站点 | H3: 目的仓代码 | I3: SKU | J3: 品名（自动） | K3: HS编码（自动） | L3: 报关数量 | M3: 单位（自动） | N3: 币种 | O3: FOB总价（原币） | P3: 报关汇率 | Q3: FOB总价（元）（自动） | R3: 进项发票号码 | S3: 进项发票不含税金额（元） | T3: 退税率（自动） | U3: 退税计税依据（元）（自动） | V3: 预计退税额（元）（自动） | W3: 头程物流商 | X3: 提单/运单号 | Y3: 亚马逊签收数量 | Z3: 签收完成日期 | AA3: 入仓差异（自动） | AB3: 差异处理（索赔/补发/说明） | AC3: 备注
A4: =IF(OR(B4="",C4=""),"",B4&"-"&C4) -> 530120260000000001-1 | B4: 530120260000000001 | C4: 1 | D4: 46091 | E4: 9810 | F4: FBA19DEMO001 | G4: 美国US | H4: ONT8 | I4: DEMO-A01 | J4: =IF(I4="","",IFERROR(INDEX(参数表!$D$13:$D$212,MATCH(I4,参数表!$A$13:$A$212,0)),"SKU未建档")) -> 示例商品A | K4: =IF(I4="","",IFERROR(INDEX(参数表!$F$13:$F$212,MATCH(I4,参数表!$A$13:$A$212,0)),"SKU未建档")) -> 按实际填写 | L4: 1000 | M4: =IF(I4="","",IFERROR(INDEX(参数表!$G$13:$G$212,MATCH(I4,参数表!$A$13:$A$212,0)),"SKU未建档")) -> 个 | N4: USD | O4: 6000 | P4: 7.1 | Q4: =IF(OR(O4="",P4=""),"",ROUND(O4*P4,2)) -> 42600 | R4: 示例发票001 | S4: 36000 | T4: =IF(I4="","",IFERROR(INDEX(参数表!$H$13:$H$212,MATCH(I4,参数表!$A$13:$A$212,0)),"SKU未建档")) -> 0.13 | U4: =IF(A4="","",IF(参数表!$B$6="外贸企业",IF(S4="","",S4),IF(Q4="","",Q4))) -> 36000 | V4: =IF(OR(U4="",NOT(ISNUMBER(T4))),"",ROUND(U4*T4,2)) -> 4680 | W4: 示例货代 | X4: 示例提单001 | Y4: 996 | Z4: 46132 | AA4: =IF(OR(L4="",Y4=""),"",Y4-L4) -> -4 | AB4: 4件已提交入仓索赔 | AC4: 示例
A5: =IF(OR(B5="",C5=""),"",B5&"-"&C5) -> 530120260000000001-2 | B5: 530120260000000001 | C5: 2 | D5: 46091 | E5: 9810 | F5: FBA19DEMO001 | G5: 美国US | H5: ONT8 | I5: DEMO-B02 | J5: =IF(I5="","",IFERROR(INDEX(参数表!$D$13:$D$212,MATCH(I5,参数表!$A$13:$A$212,0)),"SKU未建档")) -> 示例商品B | K5: =IF(I5="","",IFERROR(INDEX(参数表!$F$13:$F$212,MATCH(I5,参数表!$A$13:$A$212,0)),"SKU未建档")) -> 按实际填写 | L5: 500 | M5: =IF(I5="","",IFERROR(INDEX(参数表!$G$13:$G$212,MATCH(I5,参数表!$A$13:$A$212,0)),"SKU未建档")) -> 个 | N5: USD | O5: 4000 | P5: 7.1 | Q5: =IF(OR(O5="",P5=""),"",ROUND(O5*P5,2)) -> 28400 | R5: 示例发票002 | S5: 22000 | T5: =IF(I5="","",IFERROR(INDEX(参数表!$H$13:$H$212,MATCH(I5,参数表!$A$13:$A$212,0)),"SKU未建档")) -> 0.13 | U5: =IF(A5="","",IF(参数表!$B$6="外贸企业",IF(S5="","",S5),IF(Q5="","",Q5))) -> 22000 | V5: =IF(OR(U5="",NOT(ISNUMBER(T5))),"",ROUND(U5*T5,2)) -> 2860 | W5: 示例货代 | X5: 示例提单001 | Y5: 500 | Z5: 46132 | AA5: =IF(OR(L5="",Y5=""),"",Y5-L5) -> 0 | AC5: 示例
A6: =IF(OR(B6="",C6=""),"",B6&"-"&C6) | J6: =IF(I6="","",IFERROR(INDEX(参数表!$D$13:$D$212,MATCH(I6,参数表!$A$13:$A$212,0)),"SKU未建档")) | K6: =IF(I6="","",IFERROR(INDEX(参数表!$F$13:$F$212,MATCH(I6,参数表!$A$13:$A$212,0)),"SKU未建档")) | M6: =IF(I6="","",IFERROR(INDEX(参数表!$G$13:$G$212,MATCH(I6,参数表!$A$13:$A$212,0)),"SKU未建档")) | Q6: =IF(OR(O6="",P6=""),"",ROUND(O6*P6,2)) | T6: =IF(I6="","",IFERROR(INDEX(参数表!$H$13:$H$212,MATCH(I6,参数表!$A$13:$A$212,0)),"SKU未建档")) | U6: =IF(A6="","",IF(参数表!$B$6="外贸企业",IF(S6="","",S6),IF(Q6="","",Q6))) | V6: =IF(OR(U6="",NOT(ISNUMBER(T6))),"",ROUND(U6*T6,2)) | AA6: =IF(OR(L6="",Y6=""),"",Y6-L6)
A7: =IF(OR(B7="",C7=""),"",B7&"-"&C7) | J7: =IF(I7="","",IFERROR(INDEX(参数表!$D$13:$D$212,MATCH(I7,参数表!$A$13:$A$212,0)),"SKU未建档")) | K7: =IF(I7="","",IFERROR(INDEX(参数表!$F$13:$F$212,MATCH(I7,参数表!$A$13:$A$212,0)),"SKU未建档")) | M7: =IF(I7="","",IFERROR(INDEX(参数表!$G$13:$G$212,MATCH(I7,参数表!$A$13:$A$212,0)),"SKU未建档")) | Q7: =IF(OR(O7="",P7=""),"",ROUND(O7*P7,2)) | T7: =IF(I7="","",IFERROR(INDEX(参数表!$H$13:$H$212,MATCH(I7,参数表!$A$13:$A$212,0)),"SKU未建档")) | U7: =IF(A7="","",IF(参数表!$B$6="外贸企业",IF(S7="","",S7),IF(Q7="","",Q7))) | V7: =IF(OR(U7="",NOT(ISNUMBER(T7))),"",ROUND(U7*T7,2)) | AA7: =IF(OR(L7="",Y7=""),"",Y7-L7)
A8: =IF(OR(B8="",C8=""),"",B8&"-"&C8) | J8: =IF(I8="","",IFERROR(INDEX(参数表!$D$13:$D$212,MATCH(I8,参数表!$A$13:$A$212,0)),"SKU未建档")) | K8: =IF(I8="","",IFERROR(INDEX(参数表!$F$13:$F$212,MATCH(I8,参数表!$A$13:$A$212,0)),"SKU未建档")) | M8: =IF(I8="","",IFERROR(INDEX(参数表!$G$13:$G$212,MATCH(I8,参数表!$A$13:$A$212,0)),"SKU未建档")) | Q8: =IF(OR(O8="",P8=""),"",ROUND(O8*P8,2)) | T8: =IF(I8="","",IFERROR(INDEX(参数表!$H$13:$H$212,MATCH(I8,参数表!$A$13:$A$212,0)),"SKU未建档")) | U8: =IF(A8="","",IF(参数表!$B$6="外贸企业",IF(S8="","",S8),IF(Q8="","",Q8))) | V8: =IF(OR(U8="",NOT(ISNUMBER(T8))),"",ROUND(U8*T8,2)) | AA8: =IF(OR(L8="",Y8=""),"",Y8-L8)
A9: =IF(OR(B9="",C9=""),"",B9&"-"&C9) | J9: =IF(I9="","",IFERROR(INDEX(参数表!$D$13:$D$212,MATCH(I9,参数表!$A$13:$A$212,0)),"SKU未建档")) | K9: =IF(I9="","",IFERROR(INDEX(参数表!$F$13:$F$212,MATCH(I9,参数表!$A$13:$A$212,0)),"SKU未建档")) | M9: =IF(I9="","",IFERROR(INDEX(参数表!$G$13:$G$212,MATCH(I9,参数表!$A$13:$A$212,0)),"SKU未建档")) | Q9: =IF(OR(O9="",P9=""),"",ROUND(O9*P9,2)) | T9: =IF(I9="","",IFERROR(INDEX(参数表!$H$13:$H$212,MATCH(I9,参数表!$A$13:$A$212,0)),"SKU未建档")) | U9: =IF(A9="","",IF(参数表!$B$6="外贸企业",IF(S9="","",S9),IF(Q9="","",Q9))) | V9: =IF(OR(U9="",NOT(ISNUMBER(T9))),"",ROUND(U9*T9,2)) | AA9: =IF(OR(L9="",Y9=""),"",Y9-L9)
A10: =IF(OR(B10="",C10=""),"",B10&"-"&C10) | J10: =IF(I10="","",IFERROR(INDEX(参数表!$D$13:$D$212,MATCH(I10,参数表!$A$13:$A$212,0)),"SKU未建档")) | K10: =IF(I10="","",IFERROR(INDEX(参数表!$F$13:$F$212,MATCH(I10,参数表!$A$13:$A$212,0)),"SKU未建档")) | M10: =IF(I10="","",IFERROR(INDEX(参数表!$G$13:$G$212,MATCH(I10,参数表!$A$13:$A$212,0)),"SKU未建档")) | Q10: =IF(OR(O10="",P10=""),"",ROUND(O10*P10,2)) | T10: =IF(I10="","",IFERROR(INDEX(参数表!$H$13:$H$212,MATCH(I10,参数表!$A$13:$A$212,0)),"SKU未建档")) | U10: =IF(A10="","",IF(参数表!$B$6="外贸企业",IF(S10="","",S10),IF(Q10="","",Q10))) | V10: =IF(OR(U10="",NOT(ISNUMBER(T10))),"",ROUND(U10*T10,2)) | AA10: =IF(OR(L10="",Y10=""),"",Y10-L10)
A11: =IF(OR(B11="",C11=""),"",B11&"-"&C11) | J11: =IF(I11="","",IFERROR(INDEX(参数表!$D$13:$D$212,MATCH(I11,参数表!$A$13:$A$212,0)),"SKU未建档")) | K11: =IF(I11="","",IFERROR(INDEX(参数表!$F$13:$F$212,MATCH(I11,参数表!$A$13:$A$212,0)),"SKU未建档")) | M11: =IF(I11="","",IFERROR(INDEX(参数表!$G$13:$G$212,MATCH(I11,参数表!$A$13:$A$212,0)),"SKU未建档")) | Q11: =IF(OR(O11="",P11=""),"",ROUND(O11*P11,2)) | T11: =IF(I11="","",IFERROR(INDEX(参数表!$H$13:$H$212,MATCH(I11,参数表!$A$13:$A$212,0)),"SKU未建档")) | U11: =IF(A11="","",IF(参数表!$B$6="外贸企业",IF(S11="","",S11),IF(Q11="","",Q11))) | V11: =IF(OR(U11="",NOT(ISNUMBER(T11))),"",ROUND(U11*T11,2)) | AA11: =IF(OR(L11="",Y11=""),"",Y11-L11)
A12: =IF(OR(B12="",C12=""),"",B12&"-"&C12) | J12: =IF(I12="","",IFERROR(INDEX(参数表!$D$13:$D$212,MATCH(I12,参数表!$A$13:$A$212,0)),"SKU未建档")) | K12: =IF(I12="","",IFERROR(INDEX(参数表!$F$13:$F$212,MATCH(I12,参数表!$A$13:$A$212,0)),"SKU未建档")) | M12: =IF(I12="","",IFERROR(INDEX(参数表!$G$13:$G$212,MATCH(I12,参数表!$A$13:$A$212,0)),"SKU未建档")) | Q12: =IF(OR(O12="",P12=""),"",ROUND(O12*P12,2)) | T12: =IF(I12="","",IFERROR(INDEX(参数表!$H$13:$H$212,MATCH(I12,参数表!$A$13:$A$212,0)),"SKU未建档")) | U12: =IF(A12="","",IF(参数表!$B$6="外贸企业",IF(S12="","",S12),IF(Q12="","",Q12))) | V12: =IF(OR(U12="",NOT(ISNUMBER(T12))),"",ROUND(U12*T12,2)) | AA12: =IF(OR(L12="",Y12=""),"",Y12-L12)
A13: =IF(OR(B13="",C13=""),"",B13&"-"&C13) | J13: =IF(I13="","",IFERROR(INDEX(参数表!$D$13:$D$212,MATCH(I13,参数表!$A$13:$A$212,0)),"SKU未建档")) | K13: =IF(I13="","",IFERROR(INDEX(参数表!$F$13:$F$212,MATCH(I13,参数表!$A$13:$A$212,0)),"SKU未建档")) | M13: =IF(I13="","",IFERROR(INDEX(参数表!$G$13:$G$212,MATCH(I13,参数表!$A$13:$A$212,0)),"SKU未建档")) | Q13: =IF(OR(O13="",P13=""),"",ROUND(O13*P13,2)) | T13: =IF(I13="","",IFERROR(INDEX(参数表!$H$13:$H$212,MATCH(I13,参数表!$A$13:$A$212,0)),"SKU未建档")) | U13: =IF(A13="","",IF(参数表!$B$6="外贸企业",IF(S13="","",S13),IF(Q13="","",Q13))) | V13: =IF(OR(U13="",NOT(ISNUMBER(T13))),"",ROUND(U13*T13,2)) | AA13: =IF(OR(L13="",Y13=""),"",Y13-L13)
A14: =IF(OR(B14="",C14=""),"",B14&"-"&C14) | J14: =IF(I14="","",IFERROR(INDEX(参数表!$D$13:$D$212,MATCH(I14,参数表!$A$13:$A$212,0)),"SKU未建档")) | K14: =IF(I14="","",IFERROR(INDEX(参数表!$F$13:$F$212,MATCH(I14,参数表!$A$13:$A$212,0)),"SKU未建档")) | M14: =IF(I14="","",IFERROR(INDEX(参数表!$G$13:$G$212,MATCH(I14,参数表!$A$13:$A$212,0)),"SKU未建档")) | Q14: =IF(OR(O14="",P14=""),"",ROUND(O14*P14,2)) | T14: =IF(I14="","",IFERROR(INDEX(参数表!$H$13:$H$212,MATCH(I14,参数表!$A$13:$A$212,0)),"SKU未建档")) | U14: =IF(A14="","",IF(参数表!$B$6="外贸企业",IF(S14="","",S14),IF(Q14="","",Q14))) | V14: =IF(OR(U14="",NOT(ISNUMBER(T14))),"",ROUND(U14*T14,2)) | AA14: =IF(OR(L14="",Y14=""),"",Y14-L14)
A15: =IF(OR(B15="",C15=""),"",B15&"-"&C15) | J15: =IF(I15="","",IFERROR(INDEX(参数表!$D$13:$D$212,MATCH(I15,参数表!$A$13:$A$212,0)),"SKU未建档")) | K15: =IF(I15="","",IFERROR(INDEX(参数表!$F$13:$F$212,MATCH(I15,参数表!$A$13:$A$212,0)),"SKU未建档")) | M15: =IF(I15="","",IFERROR(INDEX(参数表!$G$13:$G$212,MATCH(I15,参数表!$A$13:$A$212,0)),"SKU未建档")) | Q15: =IF(OR(O15="",P15=""),"",ROUND(O15*P15,2)) | T15: =IF(I15="","",IFERROR(INDEX(参数表!$H$13:$H$212,MATCH(I15,参数表!$A$13:$A$212,0)),"SKU未建档")) | U15: =IF(A15="","",IF(参数表!$B$6="外贸企业",IF(S15="","",S15),IF(Q15="","",Q15))) | V15: =IF(OR(U15="",NOT(ISNUMBER(T15))),"",ROUND(U15*T15,2)) | AA15: =IF(OR(L15="",Y15=""),"",Y15-L15)
A16: =IF(OR(B16="",C16=""),"",B16&"-"&C16) | J16: =IF(I16="","",IFERROR(INDEX(参数表!$D$13:$D$212,MATCH(I16,参数表!$A$13:$A$212,0)),"SKU未建档")) | K16: =IF(I16="","",IFERROR(INDEX(参数表!$F$13:$F$212,MATCH(I16,参数表!$A$13:$A$212,0)),"SKU未建档")) | M16: =IF(I16="","",IFERROR(INDEX(参数表!$G$13:$G$212,MATCH(I16,参数表!$A$13:$A$212,0)),"SKU未建档")) | Q16: =IF(OR(O16="",P16=""),"",ROUND(O16*P16,2)) | T16: =IF(I16="","",IFERROR(INDEX(参数表!$H$13:$H$212,MATCH(I16,参数表!$A$13:$A$212,0)),"SKU未建档")) | U16: =IF(A16="","",IF(参数表!$B$6="外贸企业",IF(S16="","",S16),IF(Q16="","",Q16))) | V16: =IF(OR(U16="",NOT(ISNUMBER(T16))),"",ROUND(U16*T16,2)) | AA16: =IF(OR(L16="",Y16=""),"",Y16-L16)
A17: =IF(OR(B17="",C17=""),"",B17&"-"&C17) | J17: =IF(I17="","",IFERROR(INDEX(参数表!$D$13:$D$212,MATCH(I17,参数表!$A$13:$A$212,0)),"SKU未建档")) | K17: =IF(I17="","",IFERROR(INDEX(参数表!$F$13:$F$212,MATCH(I17,参数表!$A$13:$A$212,0)),"SKU未建档")) | M17: =IF(I17="","",IFERROR(INDEX(参数表!$G$13:$G$212,MATCH(I17,参数表!$A$13:$A$212,0)),"SKU未建档")) | Q17: =IF(OR(O17="",P17=""),"",ROUND(O17*P17,2)) | T17: =IF(I17="","",IFERROR(INDEX(参数表!$H$13:$H$212,MATCH(I17,参数表!$A$13:$A$212,0)),"SKU未建档")) | U17: =IF(A17="","",IF(参数表!$B$6="外贸企业",IF(S17="","",S17),IF(Q17="","",Q17))) | V17: =IF(OR(U17="",NOT(ISNUMBER(T17))),"",ROUND(U17*T17,2)) | AA17: =IF(OR(L17="",Y17=""),"",Y17-L17)
... A303: =IF(OR(B303="",C303=""),"",B303&"-"&C303) | J303: =IF(I303="","",IFERROR(INDEX(参数表!$D$13:$D$212,MATCH(I303,参数表!$A$13:$A$212,0)),"SKU未建档")) | K303: =IF(I303="","",IFERROR(INDEX(参数表!$F$13:$F$212,MATCH(I303,参数表!$A$13:$A$212,0)),"SKU未建档")) | M303: =IF(I303="","",IFERROR(INDEX(参数表!$G$13:$G$212,MATCH(I303,参数表!$A$13:$A$212,0)),"SKU未建档")) | Q303: =IF(OR(O303="",P303=""),"",ROUND(O303*P303,2)) | T303: =IF(I303="","",IFERROR(INDEX(参数表!$H$13:$H$212,MATCH(I303,参数表!$A$13:$A$212,0)),"SKU未建档")) | U303: =IF(A303="","",IF(参数表!$B$6="外贸企业",IF(S303="","",S303),IF(Q303="","",Q303))) | V303: =IF(OR(U303="",NOT(ISNUMBER(T303))),"",ROUND(U303*T303,2)) | AA303: =IF(OR(L303="",Y303=""),"",Y303-L303)

Sheet ②销售核销
A1: ② 销售核销（把每月销量分配到报关单）
A2: 按结算报告每月填写：一个月 × 一个SKU × 一个核销编号 一行。同一SKU有多票报关单时，先分配给出口日期最早的那票（先进先出），卖完再分下一票。
A3: 销售月份 | B3: 结算报告编号（Settlement ID） | C3: 站点 | D3: SKU | E3: 归属核销编号 | F3: SKU核对（自动） | G3: 售出数量 | H3: 买家退货数量（回到可售） | I3: 净售出数量（自动） | J3: 商品销售额（原币） | K3: 平台扣费分摊（原币） | L3: 净回款（原币）（自动） | M3: 收汇状态（自动） | N3: 实现销售日期 | O3: 销售佐证留存日期 | P3: 佐证留存（自动） | Q3: 备注
A4: 46143 | B4: 示例结算001 | C4: 美国US | D4: DEMO-A01 | E4: 530120260000000001-1 | F4: =IF(OR(D4="",E4=""),"",IF(IFERROR(INDEX(①出口报关!$I$4:$I$303,MATCH(E4,①出口报关!$A$4:$A$303,0)),"")=D4,"一致","SKU与报关单不符")) -> 一致 | G4: 300 | H4: 10 | I4: =IF(AND(G4="",H4=""),"",N(G4)-N(H4)) -> 290 | J4: 8997 | K4: 3600 | L4: =IF(AND(J4="",K4=""),"",N(J4)-N(K4)) -> 5397 | M4: =IF(B4="","",IF(COUNTIFS(③回款收汇!$A$4:$A$203,B4,③回款收汇!$R$4:$R$203,">0")>0,"已收汇","待收汇")) -> 已收汇 | N4: 46173 | O4: 46183 | P4: =IF(N4="","",IF(O4="",IF(TODAY()-N4>15,"已超15天未留存","待留存"),IF(O4-N4<=15,"及时","超期"))) -> 及时 | Q4: 示例
A5: 46143 | B5: 示例结算001 | C5: 美国US | D5: DEMO-B02 | E5: 530120260000000001-2 | F5: =IF(OR(D5="",E5=""),"",IF(IFERROR(INDEX(①出口报关!$I$4:$I$303,MATCH(E5,①出口报关!$A$4:$A$303,0)),"")=D5,"一致","SKU与报关单不符")) -> 一致 | G5: 200 | H5: 0 | I5: =IF(AND(G5="",H5=""),"",N(G5)-N(H5)) -> 200 | J5: 7998 | K5: 3200 | L5: =IF(AND(J5="",K5=""),"",N(J5)-N(K5)) -> 4798 | M5: =IF(B5="","",IF(COUNTIFS(③回款收汇!$A$4:$A$203,B5,③回款收汇!$R$4:$R$203,">0")>0,"已收汇","待收汇")) -> 已收汇 | N5: 46173 | O5: 46183 | P5: =IF(N5="","",IF(O5="",IF(TODAY()-N5>15,"已超15天未留存","待留存"),IF(O5-N5<=15,"及时","超期"))) -> 及时 | Q5: 示例
A6: 46174 | B6: 示例结算002 | C6: 美国US | D6: DEMO-A01 | E6: 530120260000000001-1 | F6: =IF(OR(D6="",E6=""),"",IF(IFERROR(INDEX(①出口报关!$I$4:$I$303,MATCH(E6,①出口报关!$A$4:$A$303,0)),"")=D6,"一致","SKU与报关单不符")) -> 一致 | G6: 400 | H6: 5 | I6: =IF(AND(G6="",H6=""),"",N(G6)-N(H6)) -> 395 | J6: 11996 | K6: 4800 | L6: =IF(AND(J6="",K6=""),"",N(J6)-N(K6)) -> 7196 | M6: =IF(B6="","",IF(COUNTIFS(③回款收汇!$A$4:$A$203,B6,③回款收汇!$R$4:$R$203,">0")>0,"已收汇","待收汇")) -> 待收汇 | N6: 46203 | O6: 46223 | P6: =IF(N6="","",IF(O6="",IF(TODAY()-N6>15,"已超15天未留存","待留存"),IF(O6-N6<=15,"及时","超期"))) -> 超期 | Q6: 示例：佐证留存超期
F7: =IF(OR(D7="",E7=""),"",IF(IFERROR(INDEX(①出口报关!$I$4:$I$303,MATCH(E7,①出口报关!$A$4:$A$303,0)),"")=D7,"一致","SKU与报关单不符")) | I7: =IF(AND(G7="",H7=""),"",N(G7)-N(H7)) | L7: =IF(AND(J7="",K7=""),"",N(J7)-N(K7)) | M7: =IF(B7="","",IF(COUNTIFS(③回款收汇!$A$4:$A$203,B7,③回款收汇!$R$4:$R$203,">0")>0,"已收汇","待收汇")) | P7: =IF(N7="","",IF(O7="",IF(TODAY()-N7>15,"已超15天未留存","待留存"),IF(O7-N7<=15,"及时","超期")))
F8: =IF(OR(D8="",E8=""),"",IF(IFERROR(INDEX(①出口报关!$I$4:$I$303,MATCH(E8,①出口报关!$A$4:$A$303,0)),"")=D8,"一致","SKU与报关单不符")) | I8: =IF(AND(G8="",H8=""),"",N(G8)-N(H8)) | L8: =IF(AND(J8="",K8=""),"",N(J8)-N(K8)) | M8: =IF(B8="","",IF(COUNTIFS(③回款收汇!$A$4:$A$203,B8,③回款收汇!$R$4:$R$203,">0")>0,"已收汇","待收汇")) | P8: =IF(N8="","",IF(O8="",IF(TODAY()-N8>15,"已超15天未留存","待留存"),IF(O8-N8<=15,"及时","超期")))
F9: =IF(OR(D9="",E9=""),"",IF(IFERROR(INDEX(①出口报关!$I$4:$I$303,MATCH(E9,①出口报关!$A$4:$A$303,0)),"")=D9,"一致","SKU与报关单不符")) | I9: =IF(AND(G9="",H9=""),"",N(G9)-N(H9)) | L9: =IF(AND(J9="",K9=""),"",N(J9)-N(K9)) | M9: =IF(B9="","",IF(COUNTIFS(③回款收汇!$A$4:$A$203,B9,③回款收汇!$R$4:$R$203,">0")>0,"已收汇","待收汇")) | P9: =IF(N9="","",IF(O9="",IF(TODAY()-N9>15,"已超15天未留存","待留存"),IF(O9-N9<=15,"及时","超期")))
F10: =IF(OR(D10="",E10=""),"",IF(IFERROR(INDEX(①出口报关!$I$4:$I$303,MATCH(E10,①出口报关!$A$4:$A$303,0)),"")=D10,"一致","SKU与报关单不符")) | I10: =IF(AND(G10="",H10=""),"",N(G10)-N(H10)) | L10: =IF(AND(J10="",K10=""),"",N(J10)-N(K10)) | M10: =IF(B10="","",IF(COUNTIFS(③回款收汇!$A$4:$A$203,B10,③回款收汇!$R$4:$R$203,">0")>0,"已收汇","待收汇")) | P10: =IF(N10="","",IF(O10="",IF(TODAY()-N10>15,"已超15天未留存","待留存"),IF(O10-N10<=15,"及时","超期")))
F11: =IF(OR(D11="",E11=""),"",IF(IFERROR(INDEX(①出口报关!$I$4:$I$303,MATCH(E11,①出口报关!$A$4:$A$303,0)),"")=D11,"一致","SKU与报关单不符")) | I11: =IF(AND(G11="",H11=""),"",N(G11)-N(H11)) | L11: =IF(AND(J11="",K11=""),"",N(J11)-N(K11)) | M11: =IF(B11="","",IF(COUNTIFS(③回款收汇!$A$4:$A$203,B11,③回款收汇!$R$4:$R$203,">0")>0,"已收汇","待收汇")) | P11: =IF(N11="","",IF(O11="",IF(TODAY()-N11>15,"已超15天未留存","待留存"),IF(O11-N11<=15,"及时","超期")))
F12: =IF(OR(D12="",E12=""),"",IF(IFERROR(INDEX(①出口报关!$I$4:$I$303,MATCH(E12,①出口报关!$A$4:$A$303,0)),"")=D12,"一致","SKU与报关单不符")) | I12: =IF(AND(G12="",H12=""),"",N(G12)-N(H12)) | L12: =IF(AND(J12="",K12=""),"",N(J12)-N(K12)) | M12: =IF(B12="","",IF(COUNTIFS(③回款收汇!$A$4:$A$203,B12,③回款收汇!$R$4:$R$203,">0")>0,"已收汇","待收汇")) | P12: =IF(N12="","",IF(O12="",IF(TODAY()-N12>15,"已超15天未留存","待留存"),IF(O12-N12<=15,"及时","超期")))
F13: =IF(OR(D13="",E13=""),"",IF(IFERROR(INDEX(①出口报关!$I$4:$I$303,MATCH(E13,①出口报关!$A$4:$A$303,0)),"")=D13,"一致","SKU与报关单不符")) | I13: =IF(AND(G13="",H13=""),"",N(G13)-N(H13)) | L13: =IF(AND(J13="",K13=""),"",N(J13)-N(K13)) | M13: =IF(B13="","",IF(COUNTIFS(③回款收汇!$A$4:$A$203,B13,③回款收汇!$R$4:$R$203,">0")>0,"已收汇","待收汇")) | P13: =IF(N13="","",IF(O13="",IF(TODAY()-N13>15,"已超15天未留存","待留存"),IF(O13-N13<=15,"及时","超期")))
F14: =IF(OR(D14="",E14=""),"",IF(IFERROR(INDEX(①出口报关!$I$4:$I$303,MATCH(E14,①出口报关!$A$4:$A$303,0)),"")=D14,"一致","SKU与报关单不符")) | I14: =IF(AND(G14="",H14=""),"",N(G14)-N(H14)) | L14: =IF(AND(J14="",K14=""),"",N(J14)-N(K14)) | M14: =IF(B14="","",IF(COUNTIFS(③回款收汇!$A$4:$A$203,B14,③回款收汇!$R$4:$R$203,">0")>0,"已收汇","待收汇")) | P14: =IF(N14="","",IF(O14="",IF(TODAY()-N14>15,"已超15天未留存","待留存"),IF(O14-N14<=15,"及时","超期")))
F15: =IF(OR(D15="",E15=""),"",IF(IFERROR(INDEX(①出口报关!$I$4:$I$303,MATCH(E15,①出口报关!$A$4:$A$303,0)),"")=D15,"一致","SKU与报关单不符")) | I15: =IF(AND(G15="",H15=""),"",N(G15)-N(H15)) | L15: =IF(AND(J15="",K15=""),"",N(J15)-N(K15)) | M15: =IF(B15="","",IF(COUNTIFS(③回款收汇!$A$4:$A$203,B15,③回款收汇!$R$4:$R$203,">0")>0,"已收汇","待收汇")) | P15: =IF(N15="","",IF(O15="",IF(TODAY()-N15>15,"已超15天未留存","待留存"),IF(O15-N15<=15,"及时","超期")))
F16: =IF(OR(D16="",E16=""),"",IF(IFERROR(INDEX(①出口报关!$I$4:$I$303,MATCH(E16,①出口报关!$A$4:$A$303,0)),"")=D16,"一致","SKU与报关单不符")) | I16: =IF(AND(G16="",H16=""),"",N(G16)-N(H16)) | L16: =IF(AND(J16="",K16=""),"",N(J16)-N(K16)) | M16: =IF(B16="","",IF(COUNTIFS(③回款收汇!$A$4:$A$203,B16,③回款收汇!$R$4:$R$203,">0")>0,"已收汇","待收汇")) | P16: =IF(N16="","",IF(O16="",IF(TODAY()-N16>15,"已超15天未留存","待留存"),IF(O16-N16<=15,"及时","超期")))
F17: =IF(OR(D17="",E17=""),"",IF(IFERROR(INDEX(①出口报关!$I$4:$I$303,MATCH(E17,①出口报关!$A$4:$A$303,0)),"")=D17,"一致","SKU与报关单不符")) | I17: =IF(AND(G17="",H17=""),"",N(G17)-N(H17)) | L17: =IF(AND(J17="",K17=""),"",N(J17)-N(K17)) | M17: =IF(B17="","",IF(COUNTIFS(③回款收汇!$A$4:$A$203,B17,③回款收汇!$R$4:$R$203,">0")>0,"已收汇","待收汇")) | P17: =IF(N17="","",IF(O17="",IF(TODAY()-N17>15,"已超15天未留存","待留存"),IF(O17-N17<=15,"及时","超期")))
F18: =IF(OR(D18="",E18=""),"",IF(IFERROR(INDEX(①出口报关!$I$4:$I$303,MATCH(E18,①出口报关!$A$4:$A$303,0)),"")=D18,"一致","SKU与报关单不符")) | I18: =IF(AND(G18="",H18=""),"",N(G18)-N(H18)) | L18: =IF(AND(J18="",K18=""),"",N(J18)-N(K18)) | M18: =IF(B18="","",IF(COUNTIFS(③回款收汇!$A$4:$A$203,B18,③回款收汇!$R$4:$R$203,">0")>0,"已收汇","待收汇")) | P18: =IF(N18="","",IF(O18="",IF(TODAY()-N18>15,"已超15天未留存","待留存"),IF(O18-N18<=15,"及时","超期")))
... F603: =IF(OR(D603="",E603=""),"",IF(IFERROR(INDEX(①出口报关!$I$4:$I$303,MATCH(E603,①出口报关!$A$4:$A$303,0)),"")=D603,"一致","SKU与报关单不符")) | I603: =IF(AND(G603="",H603=""),"",N(G603)-N(H603)) | L603: =IF(AND(J603="",K603=""),"",N(J603)-N(K603)) | M603: =IF(B603="","",IF(COUNTIFS(③回款收汇!$A$4:$A$203,B603,③回款收汇!$R$4:$R$203,">0")>0,"已收汇","待收汇")) | P603: =IF(N603="","",IF(O603="",IF(TODAY()-N603>15,"已超15天未留存","待留存"),IF(O603-N603<=15,"及时","超期")))

Sheet ③回款收汇
A1: ③ 回款收汇（每份结算报告一行）
A2: 毛额、各项扣费、净额分开记，方便按毛额还原。结算净额需全部分配到「②销售核销」，分摊差异为 0 才算分完；收汇以资金进入境内银行账户为准。
A3: 结算报告编号（Settlement ID） | B3: 站点 | C3: 币种 | D3: 结算期间（起） | E3: 结算期间（止） | F3: 商品销售额 | G3: 平台佣金 | H3: FBA配送费 | I3: 仓储费 | J3: 广告费 | K3: 退款 | L3: 其他扣费 | M3: 结算净额（自动） | N3: 已分摊到报关单（自动） | O3: 分摊差异（自动） | P3: 收款渠道 | Q3: 到达收款账户日期 | R3: 收汇入境日期（境内银行入账） | S3: 境内入账银行 | T3: 入境金额（原币） | U3: 结汇日期 | V3: 结汇汇率 | W3: 结汇金额（元）（自动） | X3: 申报附言注明"跨境电商" | Y3: 收汇凭证/水单号 | Z3: 备注
A4: 示例结算001 | B4: 美国US | C4: USD | D4: 46143 | E4: 46173 | F4: 16995 | G4: 2549.25 | H4: 3150 | I4: 300 | J4: 700 | K4: 0 | L4: 100.75 | M4: =IF(F4="","",F4-N(G4)-N(H4)-N(I4)-N(J4)-N(K4)-N(L4)) -> 10195 | N4: =IF(A4="","",SUMIFS(②销售核销!$L$4:$L$603,②销售核销!$B$4:$B$603,A4)) -> 10195 | O4: =IF(OR(M4="",N4=""),"",ROUND(M4-N4,2)) -> 0 | P4: 派安盈Payoneer | Q4: 46176 | R4: 46178 | S4: 示例银行 | T4: 10195 | U4: 46179 | V4: 7.12 | W4: =IF(OR(T4="",V4=""),"",ROUND(T4*V4,2)) -> 72588.4 | X4: 是 | Y4: 示例水单001 | Z4: 示例
A5: 示例结算002 | B5: 美国US | C5: USD | D5: 46174 | E5: 46203 | F5: 11996 | G5: 1799.4 | H5: 2200 | I5: 250 | J5: 450 | K5: 0 | L5: 100.6 | M5: =IF(F5="","",F5-N(G5)-N(H5)-N(I5)-N(J5)-N(K5)-N(L5)) -> 7196 | N5: =IF(A5="","",SUMIFS(②销售核销!$L$4:$L$603,②销售核销!$B$4:$B$603,A5)) -> 7196 | O5: =IF(OR(M5="",N5=""),"",ROUND(M5-N5,2)) -> 0 | P5: 派安盈Payoneer | Q5: 46206 | W5: =IF(OR(T5="",V5=""),"",ROUND(T5*V5,2)) | Z5: 示例：尚未提现回境内
M6: =IF(F6="","",F6-N(G6)-N(H6)-N(I6)-N(J6)-N(K6)-N(L6)) | N6: =IF(A6="","",SUMIFS(②销售核销!$L$4:$L$603,②销售核销!$B$4:$B$603,A6)) | O6: =IF(OR(M6="",N6=""),"",ROUND(M6-N6,2)) | W6: =IF(OR(T6="",V6=""),"",ROUND(T6*V6,2))
M7: =IF(F7="","",F7-N(G7)-N(H7)-N(I7)-N(J7)-N(K7)-N(L7)) | N7: =IF(A7="","",SUMIFS(②销售核销!$L$4:$L$603,②销售核销!$B$4:$B$603,A7)) | O7: =IF(OR(M7="",N7=""),"",ROUND(M7-N7,2)) | W7: =IF(OR(T7="",V7=""),"",ROUND(T7*V7,2))
M8: =IF(F8="","",F8-N(G8)-N(H8)-N(I8)-N(J8)-N(K8)-N(L8)) | N8: =IF(A8="","",SUMIFS(②销售核销!$L$4:$L$603,②销售核销!$B$4:$B$603,A8)) | O8: =IF(OR(M8="",N8=""),"",ROUND(M8-N8,2)) | W8: =IF(OR(T8="",V8=""),"",ROUND(T8*V8,2))
M9: =IF(F9="","",F9-N(G9)-N(H9)-N(I9)-N(J9)-N(K9)-N(L9)) | N9: =IF(A9="","",SUMIFS(②销售核销!$L$4:$L$603,②销售核销!$B$4:$B$603,A9)) | O9: =IF(OR(M9="",N9=""),"",ROUND(M9-N9,2)) | W9: =IF(OR(T9="",V9=""),"",ROUND(T9*V9,2))
M10: =IF(F10="","",F10-N(G10)-N(H10)-N(I10)-N(J10)-N(K10)-N(L10)) | N10: =IF(A10="","",SUMIFS(②销售核销!$L$4:$L$603,②销售核销!$B$4:$B$603,A10)) | O10: =IF(OR(M10="",N10=""),"",ROUND(M10-N10,2)) | W10: =IF(OR(T10="",V10=""),"",ROUND(T10*V10,2))
M11: =IF(F11="","",F11-N(G11)-N(H11)-N(I11)-N(J11)-N(K11)-N(L11)) | N11: =IF(A11="","",SUMIFS(②销售核销!$L$4:$L$603,②销售核销!$B$4:$B$603,A11)) | O11: =IF(OR(M11="",N11=""),"",ROUND(M11-N11,2)) | W11: =IF(OR(T11="",V11=""),"",ROUND(T11*V11,2))
M12: =IF(F12="","",F12-N(G12)-N(H12)-N(I12)-N(J12)-N(K12)-N(L12)) | N12: =IF(A12="","",SUMIFS(②销售核销!$L$4:$L$603,②销售核销!$B$4:$B$603,A12)) | O12: =IF(OR(M12="",N12=""),"",ROUND(M12-N12,2)) | W12: =IF(OR(T12="",V12=""),"",ROUND(T12*V12,2))
M13: =IF(F13="","",F13-N(G13)-N(H13)-N(I13)-N(J13)-N(K13)-N(L13)) | N13: =IF(A13="","",SUMIFS(②销售核销!$L$4:$L$603,②销售核销!$B$4:$B$603,A13)) | O13: =IF(OR(M13="",N13=""),"",ROUND(M13-N13,2)) | W13: =IF(OR(T13="",V13=""),"",ROUND(T13*V13,2))
M14: =IF(F14="","",F14-N(G14)-N(H14)-N(I14)-N(J14)-N(K14)-N(L14)) | N14: =IF(A14="","",SUMIFS(②销售核销!$L$4:$L$603,②销售核销!$B$4:$B$603,A14)) | O14: =IF(OR(M14="",N14=""),"",ROUND(M14-N14,2)) | W14: =IF(OR(T14="",V14=""),"",ROUND(T14*V14,2))
M15: =IF(F15="","",F15-N(G15)-N(H15)-N(I15)-N(J15)-N(K15)-N(L15)) | N15: =IF(A15="","",SUMIFS(②销售核销!$L$4:$L$603,②销售核销!$B$4:$B$603,A15)) | O15: =IF(OR(M15="",N15=""),"",ROUND(M15-N15,2)) | W15: =IF(OR(T15="",V15=""),"",ROUND(T15*V15,2))
M16: =IF(F16="","",F16-N(G16)-N(H16)-N(I16)-N(J16)-N(K16)-N(L16)) | N16: =IF(A16="","",SUMIFS(②销售核销!$L$4:$L$603,②销售核销!$B$4:$B$603,A16)) | O16: =IF(OR(M16="",N16=""),"",ROUND(M16-N16,2)) | W16: =IF(OR(T16="",V16=""),"",ROUND(T16*V16,2))
M17: =IF(F17="","",F17-N(G17)-N(H17)-N(I17)-N(J17)-N(K17)-N(L17)) | N17: =IF(A17="","",SUMIFS(②销售核销!$L$4:$L$603,②销售核销!$B$4:$B$603,A17)) | O17: =IF(OR(M17="",N17=""),"",ROUND(M17-N17,2)) | W17: =IF(OR(T17="",V17=""),"",ROUND(T17*V17,2))
... M203: =IF(F203="","",F203-N(G203)-N(H203)-N(I203)-N(J203)-N(K203)-N(L203)) | N203: =IF(A203="","",SUMIFS(②销售核销!$L$4:$L$603,②销售核销!$B$4:$B$603,A203)) | O203: =IF(OR(M203="",N203=""),"",ROUND(M203-N203,2)) | W203: =IF(OR(T203="",V203=""),"",ROUND(T203*V203,2))

Sheet ④退税核算
A1: ④ 退税申报与预退税核算
A2: 每次退税申报一行。未售货物申报预退税（HWC-YT）后，须在核算期末前按实际销售核算；到期不核算，税务机关会追回已退税款。
A3: 核销编号 | B3: SKU（自动） | C3: 出口日期（自动） | D3: 申报方式 | E3: 申报数量 | F3: 申报日期 | G3: 申报序号/关联号 | H3: 申报退税额（元） | I3: 税务办结日期 | J3: 核算期末（自动） | K3: 剩余天数（自动） | L3: 预退部分已实现销售数量（自动） | M3: 参考应退税额（元）（自动） | N3: 实际应退税额（元） | O3: 差额（元）（自动） | P3: 若现在核算应如何处理（自动） | Q3: 核算办理日期 | R3: 核算结果 | S3: 状态（自动） | T3: 收汇截止日（自动） | U3: 备注
A4: 530120260000000001-1 | B4: =IF(A4="","",IFERROR(INDEX(①出口报关!$I$4:$I$303,MATCH(A4,①出口报关!$A$4:$A$303,0)),"编号不存在")) -> DEMO-A01 | C4: =IF(A4="","",IFERROR(IF(INDEX(①出口报关!$D$4:$D$303,MATCH(A4,①出口报关!$A$4:$A$303,0))=0,"",INDEX(①出口报关!$D$4:$D$303,MATCH(A4,①出口报关!$A$4:$A$303,0))),"编号不存在")) -> 46091 | D4: 未售-海外仓预退（HWC-YT） | E4: 1000 | F4: 46101 | G4: 示例YT001 | H4: 4680 | I4: 46108 | J4: =IF(AND(D4="未售-海外仓预退（HWC-YT）",ISNUMBER(I4)),DATE(YEAR(I4)+1,4,30),"") -> 46507 | K4: =IF(J4="","",IF(Q4<>"","",J4-TODAY())) -> 190 | L4: =IF(OR(A4="",D4<>"未售-海外仓预退（HWC-YT）"),"",MIN(N(E4),MAX(0,SUMIFS(②销售核销!$I$4:$I$603,②销售核销!$E$4:$E$603,A4)-SUMIFS($E$4:$E$303,$A$4:$A$303,A4,$D$4:$D$303,"已售-按现行规定申报")))) -> 685 | M4: =IF(OR(L4="",N(E4)=0,H4=""),"",ROUND(H4/E4*L4,2)) -> 3205.8 | O4: =IF(OR(N4="",H4=""),"",ROUND(N4-H4,2)) | P4: =IF(OR(A4="",D4<>"未售-海外仓预退（HWC-YT）"),"",IF(L4=0,"仍未销售：需要调整申报，全额缴回预退税",IF(L4<N(E4),"部分已售：需要调整申报，全额冲减后按已售部分重报",IF(N4="","全部已售：填入实际应退税额后判断",IF(O4=0,"全部已售、无差异：无需调整申报","全部已售、有差异：需要调整申报"))))) -> 部分已售：需要调整申报，全额冲减后按已售部分重报 | S4: =IF(A4="","",IF(D4="","请选择申报方式",IF(D4<>"未售-海外仓预退（HWC-YT）","不涉及核算",IF(Q4<>"","已核算",IF(J4="","待税务办结",IF(K4<0,"已逾期：税务将追回预退税",IF(K4<=60,"临近截止（60天内）","待核算"))))))) -> 待核算 | T4: =IF(ISNUMBER(C4),DATE(YEAR(C4)+1,4,30),"") -> 46507 | U4: 示例
A5: 530120260000000001-2 | B5: =IF(A5="","",IFERROR(INDEX(①出口报关!$I$4:$I$303,MATCH(A5,①出口报关!$A$4:$A$303,0)),"编号不存在")) -> DEMO-B02 | C5: =IF(A5="","",IFERROR(IF(INDEX(①出口报关!$D$4:$D$303,MATCH(A5,①出口报关!$A$4:$A$303,0))=0,"",INDEX(①出口报关!$D$4:$D$303,MATCH(A5,①出口报关!$A$4:$A$303,0))),"编号不存在")) -> 46091 | D5: 未售-海外仓预退（HWC-YT） | E5: 500 | F5: 46101 | G5: 示例YT001 | H5: 2860 | I5: 46108 | J5: =IF(AND(D5="未售-海外仓预退（HWC-YT）",ISNUMBER(I5)),DATE(YEAR(I5)+1,4,30),"") -> 46507 | K5: =IF(J5="","",IF(Q5<>"","",J5-TODAY())) -> 190 | L5: =IF(OR(A5="",D5<>"未售-海外仓预退（HWC-YT）"),"",MIN(N(E5),MAX(0,SUMIFS(②销售核销!$I$4:$I$603,②销售核销!$E$4:$E$603,A5)-SUMIFS($E$4:$E$303,$A$4:$A$303,A5,$D$4:$D$303,"已售-按现行规定申报")))) -> 200 | M5: =IF(OR(L5="",N(E5)=0,H5=""),"",ROUND(H5/E5*L5,2)) -> 1144 | O5: =IF(OR(N5="",H5=""),"",ROUND(N5-H5,2)) | P5: =IF(OR(A5="",D5<>"未售-海外仓预退（HWC-YT）"),"",IF(L5=0,"仍未销售：需要调整申报，全额缴回预退税",IF(L5<N(E5),"部分已售：需要调整申报，全额冲减后按已售部分重报",IF(N5="","全部已售：填入实际应退税额后判断",IF(O5=0,"全部已售、无差异：无需调整申报","全部已售、有差异：需要调整申报"))))) -> 部分已售：需要调整申报，全额冲减后按已售部分重报 | S5: =IF(A5="","",IF(D5="","请选择申报方式",IF(D5<>"未售-海外仓预退（HWC-YT）","不涉及核算",IF(Q5<>"","已核算",IF(J5="","待税务办结",IF(K5<0,"已逾期：税务将追回预退税",IF(K5<=60,"临近截止（60天内）","待核算"))))))) -> 待核算 | T5: =IF(ISNUMBER(C5),DATE(YEAR(C5)+1,4,30),"") -> 46507 | U5: 示例
B6: =IF(A6="","",IFERROR(INDEX(①出口报关!$I$4:$I$303,MATCH(A6,①出口报关!$A$4:$A$303,0)),"编号不存在")) | C6: =IF(A6="","",IFERROR(IF(INDEX(①出口报关!$D$4:$D$303,MATCH(A6,①出口报关!$A$4:$A$303,0))=0,"",INDEX(①出口报关!$D$4:$D$303,MATCH(A6,①出口报关!$A$4:$A$303,0))),"编号不存在")) | J6: =IF(AND(D6="未售-海外仓预退（HWC-YT）",ISNUMBER(I6)),DATE(YEAR(I6)+1,4,30),"") | K6: =IF(J6="","",IF(Q6<>"","",J6-TODAY())) | L6: =IF(OR(A6="",D6<>"未售-海外仓预退（HWC-YT）"),"",MIN(N(E6),MAX(0,SUMIFS(②销售核销!$I$4:$I$603,②销售核销!$E$4:$E$603,A6)-SUMIFS($E$4:$E$303,$A$4:$A$303,A6,$D$4:$D$303,"已售-按现行规定申报")))) | M6: =IF(OR(L6="",N(E6)=0,H6=""),"",ROUND(H6/E6*L6,2)) | O6: =IF(OR(N6="",H6=""),"",ROUND(N6-H6,2)) | P6: =IF(OR(A6="",D6<>"未售-海外仓预退（HWC-YT）"),"",IF(L6=0,"仍未销售：需要调整申报，全额缴回预退税",IF(L6<N(E6),"部分已售：需要调整申报，全额冲减后按已售部分重报",IF(N6="","全部已售：填入实际应退税额后判断",IF(O6=0,"全部已售、无差异：无需调整申报","全部已售、有差异：需要调整申报"))))) | S6: =IF(A6="","",IF(D6="","请选择申报方式",IF(D6<>"未售-海外仓预退（HWC-YT）","不涉及核算",IF(Q6<>"","已核算",IF(J6="","待税务办结",IF(K6<0,"已逾期：税务将追回预退税",IF(K6<=60,"临近截止（60天内）","待核算"))))))) | T6: =IF(ISNUMBER(C6),DATE(YEAR(C6)+1,4,30),"")
